Workbook

Sheet Total
B3: Digital Rev (BD Phase) | C3: #REF!
B4: Digital Rev (Development Phase) | C4: #REF!
B5: DevOps Service
B6: Total | C6: #REF!
B9: ค่าเดินทาง | C9: จำนวนครั้ง | D9: ครั้งละ | E9: รวมค่าเดินทาง
E10: 0
E11: 0
E12: 0
D13: Total | E13: 0
B15: ค่าเบี้ยเลี้ยง | C15: จำนวนครั้ง | D15: ครั้งละ | E15: รวมค่าเบี้ยเลี้ยง
D16: 600 | E16: 0
D17: 600 | E17: 0
D18: 600 | E18: 0
D19: Total | E19: 0
B22: งวดการชำระเงิน PTT >> PTT Digital | C22: % | D22: จำนวนเงิน
B23: CTM Improvement 2026 Lot #1, #2
B24: งวดที่ 1 : Requirement & Design | C24: 0.3 | D24: ฿0.00
B25: งวดที่ 2 : UAT | C25: 0.5 | D25: ฿0.00
B26: งวดที่ 3 : Golive | C26: 0.2 | D26: ฿0.00 | G26: Digital Cost + Vendor | H26: #REF!
B27: CTM Improvement 2026 Promotion Management
B28: งวดที่ 1 : Requirement & Design | C28: 0.3 | D28: ฿0.00
B29: งวดที่ 2 : UAT | C29: 0.5 | D29: ฿0.00
B30: งวดที่ 3 : Golive | C30: 0.2 | D30: ฿0.00 | G30: Digital Cost + Vendor | H30: #REF!
G31: Add Overhead | H31: #REF!
B32: งวดการชำระเงิน PTT ICT >> Vendor | C32: % | D32: จำนวนเงิน | G32: Margin | H32: #REF!
D33: #REF! | G33: % Margin | H33: #REF!
D34: #REF!
C35: 0 | D35: #REF!

Sheet Resource
A1: CTM Improvement 2026 Lot #1, #2
A2: Team Information | F2: Total Manday (Day)
A4: No. | B4: Name | C4: Type | D4: Role | E4: Level | F4: Planned (Day) | G4: Manday Rate (Baht)
A5: 1 | B5: =Calsheet!D2 -> Somsunh Somburanayut | C5: Outsource | D5: Project Manager | F5: =Calsheet!D117 -> 25 | H5: 0
A6: 2 | B6: =Calsheet!E2 -> KRITSADA POOLWAN | C6: Outsource | D6: Business Analyst | F6: =Calsheet!E117 -> 71 | H6: 0
A7: 3 | B7: =Calsheet!F2 -> WIPAVEE PETCHREON | C7: Outsource | D7: System Analyst | F7: =Calsheet!F117 -> 90 | H7: 0
A8: 4 | B8: =Calsheet!G2 -> SUWIT KLANGCHAWIANG | C8: Outsource | D8: Developer Full Stack | F8: =Calsheet!G117 -> 34
A9: 5 | B9: =Calsheet!H2 -> KHAJORN WONGSILP | C9: Outsource | D9: Developer Full Stack | F9: =Calsheet!H117 -> 25
A10: 6 | B10: =Calsheet!I2 -> NATTHAPONG PUTTHIWONG | C10: Outsource | D10: Developer Full Stack | F10: =Calsheet!I117 -> 57
A11: 7 | B11: =Calsheet!J2 -> Gittipong Khaodee | C11: Outsource | D11: Developer Full Stack | F11: =Calsheet!J117 -> 41
A12: 8 | B12: =Calsheet!K2 -> Thanachai Ardchon | C12: Outsource | D12: Developer Full Stack | F12: =Calsheet!K117 -> 21
A13: 9 | B13: =Calsheet!L2 -> Soros Laohaprapa | C13: Outsource | D13: Developer Full Stack | F13: =Calsheet!L117 -> 21
A14: 10 | B14: =Calsheet!M2 -> Thanadol Lerdsakcharoenkul | C14: Outsource | D14: Security | F14: =Calsheet!M117 -> 3 | H14: 0
H15: 0
A16: CTM Improvement 2026 Promotion Management
A17: Team Information | F17: Total Manday (Day)
A19: No. | B19: Name | C19: Type | D19: Role | E19: Level | F19: Planned (Day) | G19: Manday Rate (Baht)
A20: 1 | B20: Somsunh Somburanayut | C20: Outsource | D20: Project Manager | F20: =Calsheet!D172 -> 10 | H20: 0
A21: 2 | B21: KRITSADA POOLWAN | C21: Outsource | D21: Business Analyst | F21: =Calsheet!E172 -> 19 | H21: 0
A22: 3 | B22: WIPAVEE PETCHREON | C22: Outsource | D22: System Analyst | F22: =Calsheet!F172 -> 23 | H22: 0
A23: 4 | B23: SUWIT KLANGCHAWIANG | C23: Outsource | D23: Developer Full Stack | F23: =Calsheet!G172 -> 5
A24: 5 | B24: KHAJORN WONGSILP | C24: Outsource | D24: Developer Full Stack | F24: =Calsheet!H172 -> 5
A25: 6 | B25: NATTHAPONG PUTTHIWONG | C25: Outsource | D25: Developer Full Stack | F25: =Calsheet!I172 -> 15
A26: 7 | B26: Gittipong Khaodee | C26: Outsource | D26: Developer Full Stack | F26: =Calsheet!J172 -> 13
A27: 8 | B27: Soros Laohaprapa | C27: Outsource | D27: Developer Full Stack | F27: =Calsheet!L172 -> 4
A28: 9 | B28: Thanadol Lerdsakcharoenkul | C28: Outsource | D28: Security | F28: =Calsheet!M172 -> 3 | H28: 0
A30: Other Information | C30: Total Amount (Baht)
A31: 1 | B31: Hardware | C31: -
A32: 2 | B32: Software | C32: -
A33: 3 | B33: License | C33: -
A34: 4 | B34: Allowance | C34: -
A35: 5 | B35: ค่าดำเนินโครงการโดยที่ปรึกษาภายนอก | C35: -
A36: 6 | B36: DevOps Service
A38: หมายเหตุ ถ้ามีประเภทค่าใช้จ่ายอื่นๆ เพิ่มเติมใน Project เพิ่ม Row ได้

Sheet Calsheet
A1: Phase | C1: Function Detail | D1: PM | E1: BA | F1: SA | G1: Development | M1: Security
D2: Somsunh Somburanayut | E2: KRITSADA POOLWAN | F2: WIPAVEE PETCHREON | G2: SUWIT KLANGCHAWIANG | H2: KHAJORN WONGSILP | I2: NATTHAPONG PUTTHIWONG | J2: Gittipong Khaodee | K2: Thanachai Ardchon | L2: Soros Laohaprapa | M2: Thanadol Lerdsakcharoenkul | N2: DGT Prioritize
A3: Phase I | B3: Project Preparation
C4: Project Management | D4: 3
C5: Create Project Plan, Other Plans and Integrate to Project Plan
C6: Kick Off Project | E6: 0.5 | F6: 0.5
C7: Progress Report
A8: Phase II | B8: Requirement and Sesign Phase
C9: Project Management | D9: 5
C10: Requirement Spec. | E10: 6 | F10: 1
C11: Review and Confirm Requirement Spec. | E11: 3 | F11: 1
C12: Design Spec. | E12: 1 | F12: 7
C13: Review and Confirm Design Spec. | E13: 1 | F13: 3
A14: Phase III | B14: Build
C15: Project Management | D15: 15
C16: Development
B17: 1 | C17: เพิ่มรายงาน Hi-Po for Staff และ Hi-Po for Management โดยให้มีการเปรียบเทียบข้อมูล Potential ของพนักงานในปีปัจจุบัน (ปีที่เลือก Year) เทียบกับข้อมูล Potential ของพนักงานในปีก่อนหน้า (Year-1) | E17: 0.5 | F17: 0.5 | L17: 4 | N17: 46235
B18: 2 | C18: ฟังก์ชันให้สามารถเพิ่ม/ลด รายชื่อพนักงานได้เองในระบบ เนื่องจากเมื่อสร้าง Period แล้ว รายชื่อพนักงานจะถูก freeze ไม่สามารถเปลี่ยนแปลงได้ | E18: 1 | F18: 1 | J18: 4 | N18: 46204
B19: 3 | C19: ฟังก์ชันให้ user สามารถปรับปรุงข้อมูล ที่ถูก freeze หลังจากสร้าง Period ไปแล้ว ให้สามารถอัพเดตข้อมูลในกระบวนการได้ | E19: 1 | F19: 2 | I19: 7 | N19: 46204
B20: 4 | C20: ถ้าพนักงานไม่มีข้อมูล PDA ให้ระบบไม่ต้องแสดงข้อมูล 360 ด้วย | E20: 0 | F20: 1 | K20: 1 | N20: 46204
B21: 5 | C21: เพิ่มฟังก์ชันสำหรับเซต Report to ให้ใช้งานกับ Hi-Po (เหมือนกับที่ใช้งานใน Promotion) | E21: 1 | F21: 2 | I21: 9 | N21: 46204
B22: 6 | C22: ถ้าพนักงานอยู่ Professional Track: Geosciences (GG) ปกติจะเลือกได้เฉพาะ area ของ Geosciences แต่เปิดให้เลือก area ของ Petroleum Engineering ได้ด้วย ส่วนพนักงาน Professional Track: PE, EE, DWE ยังเลือกได้เฉพาะ area ของตนเองเหมือนเดิม | E22: 0 | F22: 1 | K22: 1 | N22: 46204
B23: 7 | C23: เพิ่ม Specialist Area สำหรับ Legal & Compliance และ SSHE | E23: 0 | F23: 0.5 | L23: 1 | N23: 46204
B24: 8 | C24: การนำคะแนน Leadership Attribute มาเป็นข้อมูลอ้างอิงในการพิจารณาของปีถัดไป | E24: 1 | F24: 1 | G24: 3 | N24: 46204
B25: 9 | C25: การมีการอัพเตด Staff Profile ของ Hi-Po โดยใช้ข้อมูลพื้นฐานเหมือนกับ Promotion และเพิ่มข้อมูล Assignment และ Target position | E25: 1 | F25: 1 | G25: 4 | N25: 46204
B26: 10 | C26: ฟังก์ชัน Hi-Po Criteria for Staff (Management and Specialist) ให้เพิ่มเงื่อนไข อายุใน Pre-screening | E26: 1 | F26: 1 | J26: 3 | N26: 46204
B27: 11 | C27: ข้อมูล Evidence ที่ต้องระบุเมื่อพนักงานถูกเลือกเป็น Hi-Po Staff ให้รองรับการแนบไฟล์ | E27: 1 | F27: 1 | K27: 3 | N27: 46204
B28: 12 | C28: เพิ่มฟังก์ชันให้ Line สามารถดูผลการพิจารณาของพนักงาน หลังจาก CRB ยืนยันแล้ว โดยระบบแสดง Potential สุดท้าย | E28: 0.5 | F28: 0.5 | J28: 4 | N28: 46204
B29: 13 | C29: ปรับปรุงเงื่อนไขของรายชื่อคนที่จะเป็น Rater ปรับเป็น JG 13 and above ให้ Principal, Specialist, VP attach, National Staff and CT/CX ด้วย | E29: 0 | F29: 0.5 | K29: 1 | N29: 46204
B30: 14 | C30: รองรับกรณีที่พนักงานในกระบวนการได้ถูกโปรโมทเป็นระดับ Management ให้ระบบทำการ Inactive พนักงาน เพื่อไม่ต้องแสดงรายชื่อ และให้ไปเพิ่มรายชื่อของพนักงานในโมดูล Hi-Po for Management ในกรณีที่อยู่ในช่วงเวลาเดียวกับโมดูล Hi-Po for Staff | E30: 0.5 | F30: 0.5 | J30: 1 | N30: 46204
B31: 15 | C31: ฟังก์ชันให้ HR แอดมินสามารถถอยสถานะของระบบได้ ในแต่ละขั้นตอน | E31: 0.5 | F31: 1 | I31: 4 | N31: 46204
B32: 16 | C32: เพิ่มรายงาน Rater Task List แสดงรายชื่อพนักงาน และ Rater | E32: 1 | F32: 1 | L32: 3 | N32: 46235
B33: 17 | C33: ปรับปรุงฟังก์ชันการให้คะแนนของ Rater ให้สามารถบันทึกไว้ก่อน แล้วค่อย submit ภายหลัง | E33: 0.5 | F33: 1 | G33: 4 | N33: 46204
B34: 18 | C34: ปรับปรุงการแสดงผลของตารางที่แสดงรายชื่อพนักงาน ให้ Freeze ในส่วนหัวของตาราง พร้อมกับแสดงรายชื่อพนักงานทั้งหมดในหน้าเดียว | E34: 0 | F34: 0.5 | K34: 1 | N34: 46204
B35: 19 | C35: ฟังก์ชัน Favorite Columns ในหน้า List view เพื่อให้ผู้ใช้งานสามารถเลือกคอลัมน์ที่ต้องการแสดงได้เอง โดยรองรับการเก็บข้อมูลใน Local storage | E35: 0.5 | F35: 0.5 | K35: 3 | N35: 46204
B36: 20 | C36: หน้า Card view ให้แสดงจำนวนพนักงานในแต่ละ Potential ทั้งหมด ไม่จำกัดแค่ 50 คน | E36: 0 | F36: 0.5 | H36: 1 | N36: 46204
B37: 21 | C37: หน้า List View และ Card view สำหรับ Comment ให้เพิ่มสีไอคอนในกรณีมีข้อมูล กับไม่มีข้อมูล | E37: 0 | F37: 0.5 | H37: 1 | N37: 46204
B38: 22 | C38: Email Template ให้เพิ่มคอลัมน์โมดูล และเลือก filter ได้ | E38: 0.5 | F38: 0.5 | H38: 1 | N38: 46204
B39: 23 | C39: เพิ่ม Tools ที่ช่วยในการแสดงผล ได้แก่ ปรับขนาดตัวอักษร, ไม้บรรทัด และโฟกัส โดยแสดงในทุกหน้าของระบบ และ Master Color Configuration เพื่อเลือก Color แสดงใน Graph | E39: 0.5 | F39: 1 | G39: 4 | L39: 1 | N39: 46204
B40: 24 | C40: ปรับปรุงการแสดงผล Card view โดยให้เพิ่มข้อมูล Staff Type และปรับสีของกล่องใหม่ | E40: 0 | F40: 0.25 | H40: 1 | N40: 46204
...

Sheet Timeline
B2: Milestone | C2: Month 1 | G2: Month 2 | K2: Month 3 | O2: Month 4 | S2: Month 5 | W2: Month 6 | AA2: Month 7 | AE2: Month 8 | AI2: Month 9
C3: W1 | D3: W2 | E3: W3 | F3: W4 | G3: W1 | H3: W2 | I3: W3 | J3: W4 | K3: W1 | L3: W2 | M3: W3 | N3: W4 | O3: W1 | P3: W2 | Q3: W3 | R3: W4 | S3: W1 | T3: W2 | U3: W3 | V3: W4 | W3: W1 | X3: W2 | Y3: W3 | Z3: W4 | AA3: W1 | AB3: W2 | AC3: W3 | AD3: W4 | AE3: W1 | AF3: W2 | AG3: W3 | AH3: W4 | AI3: W1 | AJ3: W2 | AK3: W3 | AL3: W4
B4: Improvement 2026 #Lot1 | C4: Infrastructure and DevSecOps
B5: Project Preparation Phase
B6: - Project Planning
B7: - Kick Off Project
B8: Requirement and Design Phase
B9: - Get Requirement & Design
B10: - Prototype UX/UI
B11: - Requirement & Design Sign Off
B12: Build Application Phase
B13: - Development
B14: - Unit Test (UT)
B15: Testing Phase
B16: - Integration Test, System Test
... B59: - Post Golive and Support

Sheet Config
B2: Module
C3: Hi-Po
C4: Hi-Po (Spc)
C5: Hi-Po (Stf)
C6: SSP
C7: SSP (Mgr)
C8: SSP (Mgt)
C9: Promotion (Stf)
C10: Promotion (Mgt)
