Workbook
Name _Hlk175834902: 'Cost Brakedown Templete'!#REF!
Name PriceRole: 'Cost Brakedown Templete'!#REF!
Name PriceRole: #REF!
Name Role: 'Cost Brakedown Templete'!#REF!
Name Role: #REF!

Sheet Grand Total
B2: ส่วนที่ 1 | C2: ค่าดำเนินโครงการ PTT Digital
G3: =ICT_Manday!C55 -> Cost (BD Phase) | H3: =ICT_Manday!V55 -> 151500
G4: =ICT_Manday!C56 -> Cost (Development Phase) | H4: =ICT_Manday!V56 -> 1660000
G5: Total | H5: =SUM(H3:H4) -> 1811500
B9: ส่วนที่ 2 | C9: ค่าดำเนินโครงการโดยที่ปรึกษาภายนอก
G10: Vendor | H10: ='Vendor Cost'!E16 -> 1320000
G11: Vendor +10% | H11: =H10*110% -> 1452000
G12: Total | H12: =H11 -> 1452000
B15: ส่วนที่ 3 | C15: ค่าใช้จ่ายอื่นๆ
D16: PM | E16: BA | F16: Infra | G16: ค่าใช้จ่ายอื่นๆ
B17: เบี้ยเลี้ยง | C17: 600 | G17: เบี้ยเลี้ยง | H17: =(C17*D17)+(C17*E17)+(C17*F17) -> 0
B18: ที่พัก | C18: 2500 | G18: ที่พัก | H18: =(C18*D18)+(C18*E18)+(C18*F18) -> 0
B19: ค่าเดินทาง | C19: 2500 | G19: ค่าเดินทาง | H19: =(C19*D19)+(C19*E19)+(C19*F19) -> 0
G20: Total | H20: =SUM(H17:H19) -> 0
G24: Grand Total | H24: =SUM(H5+H12+H20) -> 3263500

Sheet Man-day-SAP Team
A1: No. | B1: SAP Function Module | C1: Description | D1: Comment | E1: Comment (Suthat) | F1: ABAP | G1: ABAP (New Estimate) | H1: SAP PI (New Estimate) | I1: WSO2 (New Estimate) | J1: SAP PM (New Estimate) | K1: BASIS (New Estimate) | L1: SAP Master (New Estimate) | M1: CR SAP PI | N1: CR WSO2
A2: 1 | B2: Modify ZPIPMI032 | C2: PM Notification | D2: การสร้าง Notification ผ่านทาง EIR การ Release Notification ผ่านทาง EIR | E2: 1. add new fields from ZPMPME050 2. Change user status and add long text in Notification | F2: 1 | G2: 5 | H2: =2+M2 -> 2.5 | I2: =1+N2 -> 1 | J2: 5 | K2: 2 | M2: 0.5
A3: 2 | B3: Modify ZPIPMI033 | C3: Work Order | D3: การสร้าง/แก้ไข/Release/Close Order ผ่านทาง EIR การ Close Notification ผ่านทาง EIR | E3: 1. add new fields from ZPMPME070 2. Change user status and add long text in Notification | F3: 1 | G3: 5 | H3: =2+M3 -> 2.5 | I3: =1+N3 -> 1 | J3: 5 | M3: 0.5
A4: 3 | B4: ZPIPMI034 | C4: Attach URL | D4: การแนบ URL Link ใน Notification ผ่านทาง EIR การแนบ URL Link ใน Order ผ่านทาง EIR | E4: Reuse ได้ | F4: 1 | G4: 1 | H4: =2+M4 -> 2 | I4: =1+N4 -> 1 | J4: 2
A5: 4 | B5: n/a | C5: SAP Master | D5: SAP Master - Create user + Grant Read only table PM_FL, PM_EQ, PM_NOTI, PM_ORDER, PM_ORDER_OPERATION, PM_LONGTEXT, PM_CLASS, PM_LOCATION (for ECD, EC2, ECP) | E5: ขอ view ที่ EDP Data lake ผบ ติดต่อคุณยิ้ม ธนาภรณ์ น้อยรักษา (560304) THANAPORN.KL@PTTPLC.COM PTT Digital EDP คุณ สุรฤทธิ์ Surarit Chaisuntharanon surarit.c@pttdigital.com | H5: =0+M5 -> 0 | I5: =0+N5 -> 0 | J5: 1 | L5: 2
A6: 5 | B6: ZPIPMI045 | C6: PM Time confirmation | D6: การทำ Time confirmation ผ่านทาง EIR (Reuse Pyramid) | E6: สามารถ Reuse ได้ สอบถามหน่วยงาน ผบ ติดต่อคุณยิ้ม ธนาภรณ์ น้อยรักษา (560304) THANAPORN.KL@PTTPLC.COM PTT Digital EDP คุณ สุรฤทธิ์ Surarit Chaisuntharanon surarit.c@pttdigital.com | F6: 1 | G6: 1 | H6: =2+M6 -> 2 | I6: =1+N6 -> 1 | J6: 2
A7: 6 | B7: New ZPIPMIxxx | C7: Get RAM Matrix | D7: Get Constant table ZBC_ROLLOUT_CONS REPID = ZPMPME050 and ZPMPME070 | E7: ส่ง RAM Matrix จาก SAP ให้ EIR เพื่อที่จะได้มี RAM Matrix ที่เดียว หากมีการเปลี่ยนแปลงก็จะไม่ต้องแก้ไข 2 ที่ | G7: 3 | H7: =0+M7 -> 3 | I7: =0+N7 -> 1 | J7: 1 | M7: 3 | N7: 1 | P7: 1. RFC Function 2. ต้องการเอา data จาก ZBC_ROLLOUT_CONS ขึ้น EIR | R7: Mode:- 1=GET CONSTANT 2=READ OBJECT 3.=UPDATE OBJECT IT_OBJECT_ID
A8: 7 | B8: New ZPIPMIyyy | C8: Get/Update Attachement link | D8: call FM SO_OBJECT_READ SO_OBJECT_UPDATE | E8: Call FM SO_OBJECT_READ SO_OBJECT_UPDATE | G8: 4 | H8: 3 | I8: 1 | J8: 2 | M8: 3 | N8: 1 | P8: 3. Mode Read Object 4. Mode Update Object | R8: Mode:- 1=GET CONSTANT 2=READ OBJECT 3.=UPDATE OBJECT IT_OBJECT_ID
A9: 8 | B9: Modify ZPMPME050 | C9: RAM Notification | D9: - Verify data before release (created from ZPIPMI032) - Support testing ZPIPMI032, ZPIPMI033 | G9: 2 | J9: 2
A10: 9 | B10: Modify ZPMPME070 | C10: RAM Order | D10: - Fix case Display mode IW23 --> IW33 - Support testing ZPIPMI032, ZPIPMI033 | G10: 2 | J10: 2
F11: =SUM(F2:F6) -> 4 | G11: =SUM(G2:G10) -> 23 | H11: =SUM(H2:H10) -> 15 | I11: =SUM(I2:I10) -> 6 | J11: =SUM(J2:J10) -> 22 | K11: =SUM(K2) -> 2 | L11: =SUM(L2:L10) -> 2 | M11: =SUM(M2:M7) -> 4 | N11: =SUM(N2:N7) -> 1
C14: SAP PM Sr. | D14: Suthat Lerdarunwatthana
C15: ABAP | D15: Duangjai Channum | E15: รวม | G15: =G11+H11+I11+J11+K11+L11 -> 70
C16: PI Jr. | D16: Supharoek Wutthichaipradit
C17: WSO2 Jr. | D17: Panuwat Paitakaew
C18: WSO2 Sr. | D18: Tawit Choedkiatsakul
C19: Basis Sr. | D19: Kiattisak Banlengchit
C20: SAP Master Sr. | D20: Chonticha Makkata

Sheet Man-day-SAP(bk)
A1: No. | B1: SAP Function Module | C1: Description | D1: Comment | E1: Comment (Suthat) | F1: ABAP (New Estimate) | G1: SAP PI (New Estimate) | H1: WSO2 (New Estimate) | I1: SAP PM (New Estimate) | J1: BASIS (New Estimate) | K1: SAP Master (New Estimate)
A2: 1 | B2: Modify ZPIPMI032 | C2: PM Notification | D2: การสร้าง Notification ผ่านทาง EIR การ Release Notification ผ่านทาง EIR | E2: 1. add new fields from ZPMPME050 2. Change user status and add long text in Notification 3. รองรับกระบวนการ SCF/MTCO/REWK | F2: 5 | G2: Jr. 3 | H2: Jr. 0.5 | I2: 8 | J2: 2
A3: 2 | B3: Modify ZPIPMI033 | C3: Work Order | D3: การสร้าง/แก้ไข/Release/Close Order ผ่านทาง EIR การ Close Notification ผ่านทาง EIR | E3: 1. add new fields from ZPMPME070 2. Change user status and add long text in Notification 3. รองรับกระบวนการ TECO -> ISCF/MTCO/REWK -> NOCO (BAPI_ALM_NOTIF_CLOSE ซ่อนอยู่ใน ZPIPMI033) | F3: 5 | G3: Jr. 3 | H3: Jr. 0.5 | I3: 8
A4: 3 | B4: ZPIPMI034 | C4: Attach URL | D4: การแนบ URL Link ใน Notification ผ่านทาง EIR การแนบ URL Link ใน Order ผ่านทาง EIR | E4: Reuse ได้
A5: 4 | B5: n/a | C5: SAP Master | D5: SAP Master - Create user + Grant Read only table PM_FL, PM_EQ, PM_NOTI, PM_ORDER, PM_ORDER_OPERATION, PM_LONGTEXT, PM_CLASS, PM_LOCATION (for ECD, EC2, ECP) | E5: ขอ view ที่ EDP Data lake ผบ ติดต่อคุณยิ้ม ธนาภรณ์ น้อยรักษา (560304) THANAPORN.KL@PTTPLC.COM PTT Digital EDP คุณ สุรฤทธิ์ Surarit Chaisuntharanon surarit.c@pttdigital.com
A6: 5 | B6: ZPIPMI045 | C6: PM Time confirmation | D6: การทำ Time confirmation ผ่านทาง EIR (Reuse Pyramid) | E6: สามารถ Reuse ได้ สอบถามหน่วยงาน ผบ ติดต่อคุณยิ้ม ธนาภรณ์ น้อยรักษา (560304) THANAPORN.KL@PTTPLC.COM PTT Digital EDP คุณ สุรฤทธิ์ Surarit Chaisuntharanon surarit.c@pttdigital.com
A7: 6 | B7: New ZPIPMIxxx | C7: Get RAM Matrix | D7: Get Constant table ZBC_ROLLOUT_CONS REPID = ZPMPME050 and ZPMPME070 | E7: เส้น API ใหม่ เพื่อส่งข้อมูล SAP Table ไปให้ IRIN (Table ใน IRIN) ส่ง RAM Matrix จาก SAP ให้ EIR เพื่อที่จะได้มี RAM Matrix ที่เดียว หากมีการเปลี่ยนแปลงก็จะไม่ต้องแก้ไข 2 ที่ | F7: 3 | G7: Sr. 5 | H7: Sr. 0.5 Jr. 1.5 | I7: 3 | M7: 1. RFC Function 2. ต้องการเอา data จาก ZBC_ROLLOUT_CONS ขึ้น EIR | O7: Mode:- 1=GET CONSTANT 2=READ OBJECT 3.=UPDATE OBJECT IT_OBJECT_ID
A8: 7 | B8: New ZPIPMIyyy | C8: Get/Update Attachement link | D8: call FM SO_OBJECT_READ SO_OBJECT_UPDATE | E8: เส้น API ใหม่ Call FM SO_OBJECT_READ SO_OBJECT_UPDATE | F8: 4 | G8: Sr. 5 | H8: Sr. 0.5 Jr. 1.5 | I8: 3 | M8: 3. Mode Read Object 4. Mode Update Object | O8: Mode:- 1=GET CONSTANT 2=READ OBJECT 3.=UPDATE OBJECT IT_OBJECT_ID
A9: 8 | B9: Modify ZPMPME050 | C9: RAM Notification | D9: - Verify data before release (created from ZPIPMI032) - Support testing ZPIPMI032, ZPIPMI033 | E9: แก้ไขใน SAP | F9: 2 | I9: 2
A10: 9 | B10: Modify ZPMPME070 | C10: RAM Order | D10: - Fix case Display mode IW23 --> IW33 - Support testing ZPIPMI032, ZPIPMI033 | E10: แก้ไขใน SAP | F10: 2 | I10: 2
F11: =SUM(F2:F10) -> 21 | G11: =3+3+5+5 -> 16 | H11: 5 | I11: =SUM(I2:I10) -> 26 | J11: =SUM(J2) -> 2 | K11: =SUM(K2:K10) -> 0
C14: SAP PM Sr. | D14: Suthat Lerdarunwatthana
C15: ABAP | D15: Duangjai Channum | E15: รวม | F15: =F11+G11+H11+I11+J11+K11 -> 70
C16: PI Jr. | D16: Supharoek Wutthichaipradit
C17: WSO2 Jr. | D17: Panuwat Paitakaew
C18: WSO2 Sr. | D18: Tawit Choedkiatsakul
C19: Basis Sr. | D19: Kiattisak Banlengchit
C20: SAP Master Sr. | D20: Chonticha Makkata

Sheet ICT_Manday
A1: โครงการ ENH-PTT-EIR
A2: (ระยะเวลาโครงการ 210 วัน)
A3: Phase | B3: Details | C3: Deliverables | D3: PM | E3: BA | F3: Tester | G3: SA | H3: SA | I3: SAP PM | J3: ABAP | K3: SAP PI | L3: SAP PI | M3: Basis | N3: SAP Master | O3: WSO2 | P3: WSO2 | Q3: ATA/B | R3: ATA/B | S3: Azure AD, B2C Developer zpachara.s | T3: Infra Server DevOps zpatchara.m | U3: Security thanadol.l | V3: Vendor
D4: Wilaiwan | E4: Krittiya | F4: Deonghatai | G4: Krittiya | H4: Deonghatai | I4: TUNNAPAT PISUTPAKORN | J4: Duangjai | K4: Anucha Tangsakul | L4: Junior Supharoek Wutthichaipradit | M4: Kiattisak | N4: Chonticha | O4: Panuwat | P4: Tawit | Q4: Surarit | R4: Kawin | T4: IFM/O
A5: Business Development | B5: Gather Initial Requirements | C5: Proposal, TOR | D5: 2 | E5: =1+1 -> 2 | Q5: 3 | R5: 3
B6: Vendor Selection
B7: Impact analyst | D7: 1 | E7: 1
A8: Project Planning | B8: Kick-Off Meeting | D8: 0.5 | E8: 0.5
B9: Create Project Plan, Other Plans and Integrate to Project Plan | D9: 0.25
B10: WBS & Risk Management | D10: 0.25
B11: Control & Monitoring | D11: 8
B12: Prepare and setup Development Environment | D12: 1 | G12: 1 | S12: 1 | T12: 3
A13: Requirement Development | B13: Gather Requirement Details | D13: 2 | E13: =2+1 -> 3
B14: Create Requirement Specification | D14: 1 | E14: 1
B15: Peer Review Requirement Specification | D15: 0.5 | E15: 0.5
B16: Confirm Requirement Specification with Customer | D16: 0.5 | E16: 0.5
B17: Create Business Scenario Test Script | D17: 0.5 | E17: 0.5
B18: Sign off Requirement Specification | D18: 0.5
B19: Create Baseline for Design(CM)
A20: Design | B20: Create Design Specification | D20: 0.5 | E20: 1
B21: Peer Review Design Specification | C21: Sign-Off Requirement & Design Specification | D21: 0.5 | E21: 1
B22: Clarify Design with Customer | D22: 1 | E22: =0.5+0.5 -> 1
B23: Sign off Design Specification | D23: 0.5
B24: Peer Review Technical Specification | D24: 1 | G24: 1
A25: Development | B25: Coding & Config | G25: =1+1 -> 2
B26: Connect SAP | I26: 25 | J26: 21 | K26: 10 | L26: 6 | M26: 2 | P26: 5
B27: Connect WSO2
B28: Functional Unit Test | F28: 1
B29: Integretion Test | D29: 1 | F29: 1
A30: Testing | B30: System Integration Test | D30: 1 | E30: 1 | F30: 2
B31: User Acceptance Test | D31: 2 | E31: 2 | F31: 3
B32: Perform Security Test & Load Test & Source code GIT hub | F32: 1 | U32: 3
B33: Source Code Scan (Coverity and Black Duck) | H33: 1
B34: Container Image Scan (Trivy) | H34: 1
B35: Security Scan (OWASP ZAP) | H35: 1
B36: Quality Scan (SonarQube) | H36: 1
B37: Automatic Test (Robot framework) | H37: 1
B38: Performance Test (JMeter) | H38: 1
B39: Create Baseline for Final Preparation
A40: Final Preparation | B40: Develop Deployment Plan & Readiness Checklist | D40: 0.5
...

Sheet Vendor Cost
C2: โครงการ ENH-PTT-EIR
C3: Vendor : Look social
C5: Order | D5: Description | E5: Cost
C6: 1 | D6: ค่าปรับปรุงระบบงานระบบ EIR ส่วน Web | E6: 860000
C7: 2 | D7: ค่าปรับปรุงระบบงานระบบ EIR ส่วนการสร้าง view ใหม่ จำนวน 12 view เพื่อส่งให้ POWER BI | E7: 460000
D14: Total | E14: =SUM(E6:E13) -> 1320000
D15: Discount
D16: Grand Total | E16: =E14-E15 -> 1320000
D17: ราคานี้ยังไม่รวม Vat 7%
D22: 1. ชำระงวดแรก | E22: 1 | F22: =E7*E22 -> 460000 | G22: ตามมูลค่าของโครงการเมื่อส่งมอบเอกสาร Sign-Off Requirement & Design
D23: 2. ชำระงวดที่สอง | F23: =E7*E23 -> 0 | G23: ตามมูลค่าของโครงการเมื่อส่งมอบเอกสาร Sign-Off Go live
D24: 3. ชำระงวดที่สาม | F24: =E7*E24 -> 0

Sheet Project Timeline
C2: Month 1 | G2: Month 2 | K2: Month 3 | O2: Month 4 | S2: Month 5 | W2: Month 6 | AA2: Month 7
C3: W1 | D3: W2 | E3: W3 | F3: W4 | G3: W1 | H3: W2 | I3: W3 | J3: W4 | K3: W1 | L3: W2 | M3: W3 | N3: W4 | O3: W1 | P3: W2 | Q3: W3 | R3: W4 | S3: W1 | T3: W2 | U3: W3 | V3: W4 | W3: W1 | X3: W2 | Y3: W3 | Z3: W4 | AA3: W1 | AB3: W2 | AC3: W3 | AD3: W4
A4: 1 | B4: Kick-off
A5: 2 | B5: Requirement
A6: 3 | B6: Design
A7: 4 | B7: Development & Unit Test
A8: 5 | B8: System Integration Test
A9: 6 | B9: User Acceptance Test
A10: 7 | B10: Training
A11: 8 | B11: Deployment & Go-Live
J13: 60 | X13: 165 | AD13: 210

Sheet Project detail work plan
A1: การทำ Project manage และการทำเอกสารที่เกี่ยวข้อง
A2: No | B2: Phase | C2: Work Breakdown Structure | D2: On Site(Y/N)
A3: 1 | B3: Business Development | C3: Proposal Complete | G3: 46055 | H3: =G3+210 -> 46265
A4: 2 | B4: Project Preparation | C4: Kick-Off Project
A5: 3 | B5: Requirement | C5: Gather Detailed Requirement meeting #1
A6: 4 | B6: Requirement | C6: Gather Detailed Requirement metting #2
A7: 5 | B7: Requirement | C7: Gather Detailed Requirement metting #3
A8: 6 | B8: Requirement | C8: Internal review requirement summary, Review requirement summary
A9: 7 | B9: Requirement | C9: Submit Requirement Specification document
A10: 8 | B10: Requirement | C10: Review & Confirm Requirement Specification document
A11: 9 | B11: Requirement | C11: Requirement specification (Sign-Off)
A12: 10 | B12: Design | C12: Gather Detailed Design meeting #1
A13: 11 | B13: Design | C13: Gather Detailed Design meeting #2
A14: 12 | B14: Design | C14: Gather Detailed Design meeting #3 | D14: Y
A15: 13 | B15: Design | C15: Review Design summary
A16: 14 | B16: Design | C16: Submit Design Specification document
A17: 15 | B17: Design | C17: Review & Confirm Design Specification document
A18: 16 | B18: Design | C18: Design pecification (Sign-Off)
A19: 17 | B19: Development | C19: Development
A20: 18 | B20: Development | C20: Unit test on functions & features Along with Pipeline(DevOps)
A21: 19 | B21: Test | C21: System Integration Test (SIT)#1
A22: 20 | B22: Test | C22: System Integration Test (SIT)#2
A23: 21 | B23: Test | C23: System Integration Test (SIT)#3
A24: 22 | B24: Test | C24: User Acceptance Test (UAT)#1
A25: 23 | B25: Test | C25: User Acceptance Test (UAT)#2
A26: 24 | B26: Test | C26: User Acceptance Test (UAT)#3 | D26: Y
A27: 25 | B27: Test | C27: Source code scan, Web scan, Load Test Along with Pipeline(DevOps)
A28: 26 | B28: Test | C28: User Acceptance Test (UAT) (Sign-Off)
A29: 27 | B29: Deployment | C29: Training The Trainer #Reliability | D29: Y
A30: 28 | B30: Deployment | C30: Training The Trainer #Integrity | D30: Y
A31: 29 | B31: Deployment | C31: Training Application support
A32: 30 | B32: Deployment | C32: Submit User & Admin Manual, Technical Manual
A33: 31 | B33: Deployment | C33: Data Conversion
A34: 32 | B34: Deployment | C34: Deployment
A35: 33 | B35: Go-Live | C35: Go-Live
A36: 34 | B36: Go-Live | C36: Go-Live (Sign-off)
A37: 35 | B37: Support after Go-Live | C37: Support after Go-Live
A38: 36 | B38: Support after Go-Live | C38: Survey Customer Satisfaction
A39: 37 | B39: Support after Go-Live | C39: Project Completion document
A40: 38 | B40: Support after Go-Live | C40: Project Completion document
...

Sheet Scope
A1: No | B1: Scope
A2: 1 | B2: กรณี Notification M1, PM01 ที่แจ้งซ่อมโดย Inspection (ประเภทงานแจ้งซ่อมในระบบ EIR)
B3: 1.1 SAP เพิ่มเส้น API ส่ง RAM Matrix จาก SAP ให้ EIR เพื่อที่จะได้มี RAM Matrix ที่เดียว หากมีการเปลี่ยนแปลงก็จะไม่ต้องแก้ไข 2 ที่
B4: 1.2 SAP ต้องแก้ไขเพิ่มการส่งข้อมูล new field (Prioritization) , Change user status และเพิ่ม long text ใน Notification
B5: 1.3 SAP เพิ่มเส้นแก้ไข Notification เพื่อรองรับการตรวจงานของ Inspection ในกรณีมีการ Rework ต้องแก้ไขเพื่อ update เส้น Notification เป็น MTCO, INPR REWK
B6: 1.4 EIR ต้องเพิ่มการดึงข้อมูลจาก SAP เพื่อดึงข้อมูล RAM Matrix มาแสดงในระบบ เพื่อรองรับการประเมินในระบบ EIR
B7: 1.5 EIR ต้องเพิ่มการส่งข้อมูล Priorities และการประเมิน RAM เพื่อ Update Notification และสามารถส่งข้อมูลไป Create & Release Notification ในระบบ SAP ได้
B8: 1.6 EIR ต้องเรียกเส้น Notification เพื่อ update สถานะ Notification กรณีมีการ Rework กลับไปที่ระบบ SAP และสามารถแสดงสถานะของ Work order กรณีมีการเปลี่ยนแปลงจากการ Rework ได้
A9: 2 | B9: กรณี Notification M1, PM01 ที่แจ้งซ่อมมาที่ Inspection (ประเภทงาน Service ในระบบ EIR)
B10: 2.1 SAP ต้องแก้ไขเพิ่มการส่งข้อมูล new field(prioritization) ใน work order และเพิ่ม long text ใน Notification
B11: 2.2 EIR ต้องสามารถ Update ข้อมูล Notification ส่งข้อมูล Priorities และการประเมิน RAM ที่ update จาก inspection กลับไปที่ระบบ SAP เพื่อทำการ create & release work order จากระบบ EIR ไปที่ระบบ SAP ได้
A12: 3 | B12: พัฒนาระบบ EIR ให้สามารถใช้งานระบบใน Plant ผ่าน Mobile/Tablet โดยรองรับการ Login ผ่าน Azure PTT AD, Azure B2C AD โดยต้องมีการตรวจสอบข้อมูล Whitelist ของอุปกรณ์บนระบบ CA&A โดยระบบจะต้องทำการ get device id ของ Share Device ที่เป็นอุปกรณ์ Mobile/Tablet ซึ่งเป็นเครื่องส่วนกลางของ ปตท. หากเป็นรายการที่อยู่ใน Whitelist จะต้องทำการเรียก AZURE AD ที่ไม่ require การทำ MFA แบบใช้ DuO/Microsoft Authenticator และเมื่อได้ Access Key หลังการ login ผ่าน จะทำการเรียกเส้น API ของ CA&A เพื่อตรวจสอบ Role ตาม process ของ Application ที่มีอยู่แล้วในระบบ
A13: 4 | B13: ไฟล์ Summary report ปรับปรุงให้แสดงรูป Risk Metrix จากข้อมูล Adjust ข้อมูล Class ของอุปกรณ์ หลังจากที่ประเมินเรียบร้อย โดยข้อมูล Adjust นี้จะต้องถูกนำไปแสดงที่ summary report รวมถึง Highlight Class ที่เกิดด้วย
A14: 5 | B14: vendor เดินทาง onsite 4 ครั้ง
A15: 6 | B15: การดู log ของการ login ระบบ สำหรับการ audit
A16: 7 | B16: ดำเนินการสร้าง View ใหม่ 12 view อยู่ที่ IRIN Database และแก้ไข View “Vw_health_current” ให้อยู่ในรูป Structure ใหม่ของ IRIN 1 view เพื่อให้ POWER BI มาใช้ข้อมูล
B18: As is
B19: ข้อ 1
B32: ข้อ 2
B50: As is
B51: ข้อ 3,4
B67: To Be
B69: ข้อ 1
B84: ข้อ 2
B111: ข้อ 3,4
B126: ข้อ 7 เพิ่มการสร้าง view ใน Database เพื่อรองรับ POWER BI

Sheet Assumption
A1: Organization: | B1: PTTPLC - ตร.วบก.
A2: Application/Module: | B2: PTT GSP IRIN (EIR) (RITM0039819)
A3: Key Requirement: | B3: ปรับปรุงระบบ PTT GSP IRIN (EIR) เพื่อเชื่อมต่อกับโครงการ SAP S4 HANA ซึ่งพัฒนาใหม่ โดย PTT Digital เสนอให้ออกแบบรองรับตามข้อกำหนดด้านการรักษาความมั่นคงปลอดภัยสารสนเทศของบริษัท ปตท. จำกัด (มหาชน)
A4: พัฒนาส่วนโปรแกรม SAP | B4: พัฒนาส่วนโปรแกรม SAP
B5: 1. SAP เพิ่มเส้น API ส่ง RAM Matrix จาก SAP ให้ EIR เพื่อที่จะได้มี RAM Matrix ที่เดียว หากมีการเปลี่ยนแปลงก็จะไม่ต้องแก้ไข 2 ที่
B6: 2. SAP ต้องแก้ไขเพิ่มการส่งข้อมูล new field (Prioritization) , Change user status และเพิ่ม long text ใน Notification
B7: 3. SAP เพิ่มเส้นแก้ไข Notification เพื่อรองรับการตรวจงานของ Inspection ในกรณีมีการ Rework ต้องแก้ไขเพื่อ update เส้น Notification เป็น MTCO, INPR REWK
B8: 4. SAP ต้องแก้ไขเพิ่มการส่งข้อมูล new field(prioritization) ใน work order และเพิ่ม long text ใน Notification
A10: ปรับปรุงระบบ GSP IRIN (EIR) | B10: 1. กรณี Notification M1, PM01 ที่แจ้งซ่อมโดย Inspection (ประเภทงานแจ้งซ่อมในระบบ EIR)
B11: - EIR ต้องเพิ่มการดึงข้อมูลจาก SAP เพื่อดึงข้อมูล RAM Matrix มาแสดงในระบบ เพื่อรองรับการประเมินในระบบ EIR
B12: - EIR ต้องเพิ่มการส่งข้อมูล Priorities และการประเมิน RAM เพื่อ Update Notification และสามารถส่งข้อมูลไป Create & Release Notification ในระบบ SAP ได้
B13: - EIR ต้องเรียกเส้น Notification เพื่อ update สถานะ Notification กรณีมีการ Rework กลับไปที่ระบบ SAP และสามารถแสดงสถานะของ Work order กรณีมีการเปลี่ยนแปลงจากการ Rework ได้
B14: 2. กรณี Notification M1, PM01 ที่แจ้งซ่อมมาที่ Inspection (ประเภทงาน Service ในระบบ EIR)
B15: - EIR ต้องสามารถ Update ข้อมูล Notification ส่งข้อมูล Priorities และการประเมิน RAM ที่ update จาก inspection กลับไปที่ระบบ SAP เพื่อทำการ create & release work order จากระบบ EIR ไปที่ระบบ SAP ได้
B16: 3. ไฟล์ Summary report ปรับปรุงให้แสดงรูป Risk Metrix จากข้อมูล Adjust ข้อมูล Class ของอุปกรณ์ หลังจากที่ประเมินเรียบร้อย โดยข้อมูล Adjust นี้จะต้องถูกนำไปแสดงที่ summary report รวมถึง Highlight Class ที่เกิดด้วย
B17: 4. งาน Routine/Service หลังตรวจเจอปัญหา AB ก่อนที่จะออก Noti เพื่อแจ้งซ่อม ต้องเพิ่ม Step สำหรับการระบุหน่วยงาน และผู้รับผิดชอบก่อนที่จะ Submit Report ให้ผู้อนุมัติพิจารณาอนุมัติ
B18: 5. พัฒนาหน้าจอสำหรับการดู Log การใช้งานระบบ ว่าใครสร้าง แก้ไข หรือลบอะไรไปบ้าง เนื่องจากปัจจุบันยังต้องเข้าไปดูใน Database เท่านั้น จึงพัฒนาหน้า Interface เพิ่มบน Web เพื่อดู Log การใช้งานระบบของ User Role Super Admin หรือ Role อื่นๆที่เกี่ยวข้อง
A19: เพิ่ม Feature การเข้าใช้งานใน Plant | B19: พัฒนาระบบ EIR ให้สามารถใช้งานระบบใน Plant ผ่าน Mobile/Tablet โดยต้องมีการตรวจสอบข้อมูล Whitelist ของอุปกรณ์ โดยระบบจะต้องทำการ get device id ของ Share Device ที่เป็นอุปกรณ์ Mobile/Tablet ซึ่งเป็นเครื่องส่วนกลางของ ปตท. หากเป็นรายการที่อยู่ใน Whitelist จะต้องทำการเรียก AZURE AD ที่ไม่ require การทำ MFA แบบใช้ Microsoft Authenticator
A20: สร้าง view รองรับ POWER BI | B20: ดำเนินการสร้าง View ใหม่ 12 view อยู่ที่ IRIN Database และแก้ไข View “Vw_health_current” ให้อยู่ในรูป Structure ใหม่ของ IRIN 1 view เพื่อให้ POWER BI มาใช้ข้อมูล
A21: Assumption: | B21: 1. การตรวจสอบข้อมูล Whitelist ของอุปกรณ์ จะพิจารณาว่ามีการเก็บข้อมูล Whitelist ของอุปกรณ์ที่ระบบ CA&A แล้ว ระบบจะดึงข้อมูลอุปกรณ์ Share Device ที่ระบบ CA&A แต่หากที่ระบบ CA&A ยังไม่มีข้อมูล Whitelist จะมีการจัดเก็บข้อมูลอุปกรณ์ที่ระบบ EIR เอง
A22: Testing: | B22: Unit test / System Integration Test / User Acceptance Test
B23: เฉพาะกระบวนการ, แบบฟอร์มและรายงานที่มีการปรับปรุง หรือพัฒนาขึ้นใหม่
A24: Training: | B24: Training Material (Power Point) และจัดสอน Key User แบบ Train the Trainer
A25: Data Conversion: | B25: -
A26: Duration | B26: 210 วัน
A27: Budget: | B27: 3263500
A28: Target Go-Live: | B28: 46266
A29: Out of Scope: | B29: 1. การทำ Data migration
B30: 2. การพัฒนาที่อยู่นอกเหนือขอบเขตงานที่นำเสนอ
A31: Remarks | B31: การ Support เป็น Ticket Base และไม่มีอุปกรณ์เพิ่มเติม

Sheet Breakdown
A1: No. | B1: Item | C1: Price Breakdown | D1: % Price Breakdown
A2: 1.1 | B2: Project Management | C2: 434000 | D2: =SUM(C2:C3)/C27*100 -> 18.752873 | F2: Group 1 | G2: Group 2 | H2: Group 3 | I2: Total
A3: 1.2 | B3: Requirement Gathering | C3: 178000 | E3: Bath | F3: =SUM(C2:C3) -> 612000 | G3: =SUM(C5:C22) -> 2386000 | H3: =SUM(C23:C26) -> 265500 | I3: =SUM(F3:H3) -> 3263500
A4: 2 | B4: Business Requirements Task : Analysis & Design, Program coding, Unit test | D4: =SUM(C4:C22)/C27*100 -> 73.11169 | E4: Rate | F4: =F3/I3 -> 0.18752873 | G4: =G3/I3 -> 0.7311169 | H4: =H3/I3 -> 0.081354374
A5: 2.1 | B5: พัฒนาส่วนโปรแกรม SAP | C5: 747500
B6: 2.1.1 SAP เพิ่มเส้น API ส่ง RAM Matrix จาก SAP ให้ EIR เพื่อที่จะได้มี RAM Matrix ที่เดียว หากมีการเปลี่ยนแปลงก็จะไม่ต้องแก้ไข 2 ที่
B7: 2.2.2 SAP ต้องแก้ไขเพิ่มการส่งข้อมูล new field (Prioritization) , Change user status และเพิ่ม long text ใน Notification
B8: 2.2.3 SAP เพิ่มเส้นแก้ไข Notification เพื่อรองรับการตรวจงานของ Inspection ในกรณีมีการ Rework ต้องแก้ไขเพื่อ update เส้น Notification เป็น MTCO, INPR REWK
B9: 2.2.4 SAP ต้องแก้ไขเพิ่มการส่งข้อมูล new field(prioritization) ใน work order และเพิ่ม long text ใน Notification
A10: 2.2 | B10: กรณี Notification M1, PM01 ที่แจ้งซ่อมโดย Inspection (ประเภทงานแจ้งซ่อมในระบบ EIR) | C10: 220000
B11: 2.2.1 EIR ต้องเพิ่มการดึงข้อมูลจาก SAP เพื่อดึงข้อมูล RAM Matrix มาแสดงในระบบ เพื่อรองรับการประเมินในระบบ EIR
B12: 2.2.2 EIR ต้องเพิ่มการส่งข้อมูล Priorities และการประเมิน RAM เพื่อ Update Notification และสามารถส่งข้อมูลไป Create & Release Notification ในระบบ SAP ได้
B13: 2.2.3 EIR ต้องเรียกเส้น Notification เพื่อ update สถานะ Notification กรณีมีการ Rework กลับไปที่ระบบ SAP และสามารถแสดงสถานะของ Work order กรณีมีการเปลี่ยนแปลงจากการ Rework ได้
A14: 2.3 | B14: กรณี Notification M1, PM01 ที่แจ้งซ่อมมาที่ Inspection (ประเภทงาน Service ในระบบ EIR) | C14: 220000
B15: 2.3.1 EIR ต้องสามารถ Update ข้อมูล Notification ส่งข้อมูล Priorities และการประเมิน RAM ที่ update จาก inspection กลับไปที่ระบบ SAP เพื่อทำการ create & release work order จากระบบ EIR ไปที่ระบบ SAP ได้
A16: 2.4 | B16: พัฒนาระบบ EIR ให้สามารถใช้งานระบบใน Plant ผ่าน Mobile/Tablet โดยต้องมีการตรวจสอบข้อมูล Whitelist ของอุปกรณ์ โดยระบบจะต้องทำการ get device id ของ Share Device ที่เป็นอุปกรณ์ Mobile/Tablet ซึ่งเป็นเครื่องส่วนกลางของ ปตท. หากเป็นรายการที่อยู่ใน Whitelist จะต้องทำการเรียก AZURE AD ที่ไม่ require การทำ MFA แบบใช้ Microsoft Authenticator | C16: 176000
A17: 2.5 | B17: ไฟล์ Summary report ปรับปรุงให้แสดงรูป Risk Metrix จากข้อมูล Adjust ข้อมูล Class ของอุปกรณ์ หลังจากที่ประเมินเรียบร้อย โดยข้อมูล Adjust นี้จะต้องถูกนำไปแสดงที่ summary report รวมถึง Highlight Class ที่เกิดด้วย | C17: 154000
A18: 2.6 | B18: งาน Routine/Serviec หลังตรวจเจอปัญหา AB ก่อนที่จะออก Noti เพื่อแจ้งซ่อม ต้องเพิ่ม Step สำหรับการระบุหน่วยงาน และผู้รับผิดชอบก่อนที่จะ Submit Report ให้ผู้อนุมัติพิจารณาอนุมัติ | C18: 88000
A19: 2.7 | B19: พัฒนาหน้าจอสำหรับการดู Log การใช้งานระบบ ว่าใครสร้าง แก้ไข หรือลบอะไรไปบ้าง เนื่องจากปัจจุบันยังต้องเข้าไปดูใน Database เท่านั้น จึงพัฒนาหน้า Interface เพิ่มบน Web เพื่อดู Log การใช้งานระบบของ User Role Super Admin หรือ Role อื่นๆที่เกี่ยวข้อง | C19: 88000
A20: 2.8 | B20: ดำเนินการสร้าง View ใหม่ 12 view อยู่ที่ IRIN Database และแก้ไข View “Vw_health_current” ให้อยู่ในรูป Structure ใหม่ของ IRIN 1 view เพื่อให้ POWER BI มาใช้ข้อมูล | C20: 573500
A21: 3 | B21: Testing SIT, UAT | C21: 93500
A22: 4 | B22: Training, Document | C22: 25500
A23: 5 | B23: Infrastructure | C23: 93500 | D23: =SUM(C23:C26)/C27*100 -> 8.1354374
A24: 6 | B24: Security Scan | C24: 76500
A25: 7 | B25: WSO2 API Team | C25: 70000
A26: 8 | B26: Deploy Production | C26: 25500
B27: Total | C27: =SUM(C2:C26) -> 3263500 | D27: =SUM(D2:D23) -> 100

Sheet Cost Brakedown Templete
S3: Group 1 | T3: Group 2 | U3: Group 3 | V3: Total
R4: Bath | S4: =P8 -> 595500 | T4: =P15 -> 2446000 | U4: =P35 -> 212000 | V4: =SUM(S4:U4) -> 3253500
R5: Rate | S5: =S4/V4 -> 0.18303366 | T5: =T4/V4 -> 0.75180575 | U5: =U4/V4 -> 0.065160596
A8: Group 1 | B8: Project Management & Requirement | P8: =SUM(P9:P10) -> 595500 | R8: Funtional Requirement
B9: PM | P9: =SUM(ICT_Manday!D55:D56) -> 434000 | R9: Technical Requirement
B10: BA | P10: =ICT_Manday!E57 -> 161500
A13: Group 2 | B13: PPS | C13: Rate | D13: Technical Lead | E13: SA | F13: UX/UI | G13: Trainer | H13: Dev | I13: Dev (Unit Test) | J13: Tester Vendor | K13: Tester Digital | L13: Dev | M13: Tester | N13: Total withoit Unit Test | O13: Unit Test | P13: Total
L14: =SUM(L15:L16) -> 841000 | M14: =SUM(M15:M16) -> 0 | N14: =SUM(N21:N21) -> 0 | O14: =SUM(O15:O16) -> 0
A15: 2.1 | B15: Business Requirement | P15: =SUM(P16:P33) -> 2446000
A16: 1 | B16: พัฒนาส่วนโปรแกรม SAP | H16: =SUM(ICT_Manday!H57:M57) -> 841000 | L16: =SUM(E16:H16) -> 841000 | P16: =L16 -> 841000
B17: 1.1 SAP เพิ่มเส้น API ส่ง RAM Matrix จาก SAP ให้ EIR เพื่อที่จะได้มี RAM Matrix ที่เดียว หากมีการเปลี่ยนแปลงก็จะไม่ต้องแก้ไข 2 ที่
B18: 1.2 SAP ต้องแก้ไขเพิ่มการส่งข้อมูล new field (Prioritization) , Change user status และเพิ่ม long text ใน Notification
B19: 1.3 SAP เพิ่มเส้นแก้ไข Notification เพื่อรองรับการตรวจงานของ Inspection ในกรณีมีการ Rework ต้องแก้ไขเพื่อ update เส้น Notification เป็น MTCO, INPR REWK
B20: 1.4 SAP ต้องแก้ไขเพิ่มการส่งข้อมูล new field(prioritization) ใน work order และเพิ่ม long text ใน Notification
A21: 2 | B21: กรณี Notification M1, PM01 ที่แจ้งซ่อมโดย Inspection (ประเภทงานแจ้งซ่อมในระบบ EIR) | H21: =200000*110% -> 220000 | L21: =SUM(D21:H21) -> 220000 | P21: =SUM(L21:M21) -> 220000
B22: 1. EIR ต้องเพิ่มการดึงข้อมูลจาก SAP เพื่อดึงข้อมูล RAM Matrix มาแสดงในระบบ เพื่อรองรับการประเมินในระบบ EIR
B23: 2. EIR ต้องเพิ่มการส่งข้อมูล Priorities และการประเมิน RAM เพื่อ Update Notification และสามารถส่งข้อมูลไป Create & Release Notification ในระบบ SAP ได้
B24: 3. EIR ต้องเรียกเส้น Notification เพื่อ update สถานะ Notification กรณีมีการ Rework กลับไปที่ระบบ SAP และสามารถแสดงสถานะของ Work order กรณีมีการเปลี่ยนแปลงจากการ Rework ได้
A25: 3 | B25: กรณี Notification M1, PM01 ที่แจ้งซ่อมมาที่ Inspection (ประเภทงาน Service ในระบบ EIR) | H25: =200000*110% -> 220000 | L25: =SUM(D25:H25) -> 220000 | P25: =SUM(L25:M25) -> 220000
B26: 2.1 EIR ต้องสามารถ Update ข้อมูล Notification ส่งข้อมูล Priorities และการประเมิน RAM ที่ update จาก inspection กลับไปที่ระบบ SAP เพื่อทำการ create & release work order จากระบบ EIR ไปที่ระบบ SAP ได้
A27: 4 | B27: พัฒนาระบบ EIR ให้สามารถใช้งานระบบใน Plant ผ่าน Mobile/Tablet โดยรองรับการ Login ผ่าน Azure PTT AD, Azure B2C AD โดยต้องมีการตรวจสอบข้อมูล Whitelist ของอุปกรณ์บนระบบ CA&A โดยระบบจะต้องทำการ get device id ของ Share Device ที่เป็นอุปกรณ์ Mobile/Tablet ซึ่งเป็นเครื่องส่วนกลางของ ปตท. หากเป็นรายการที่อยู่ใน Whitelist จะต้องทำการเรียก AZURE AD ที่ไม่ require การทำ MFA แบบใช้ DuO/Microsoft Authenticator และเมื่อได้ Access Key หลังการ login ผ่าน จะทำการเรียกเส้น API ของ CA&A เพื่อตรวจสอบ Role ตาม process ของ Application ที่มีอยู่แล้วในระบบ | H27: =160000*110% -> 176000 | L27: =SUM(D27:H27) -> 176000 | P27: =SUM(L27:M27) -> 176000
A28: 5 | B28: ไฟล์ Summary report ปรับปรุงให้แสดงรูป Risk Metrix จากข้อมูล Adjust ข้อมูล Class ของอุปกรณ์ หลังจากที่ประเมินเรียบร้อย โดยข้อมูล Adjust นี้จะต้องถูกนำไปแสดงที่ summary report รวมถึง Highlight Class ที่เกิดด้วย | H28: =140000*110% -> 154000 | L28: =SUM(D28:H28) -> 154000 | P28: =SUM(L28:M28) -> 154000
A29: 6 | B29: งาน Routine/Serviec หลังตรวจเจอปัญหา AB ก่อนที่จะออก Noti เพื่อแจ้งซ่อม ต้องเพิ่ม Step สำหรับการระบุหน่วยงาน และผู้รับผิดชอบก่อนที่จะ Submit Report ให้ผู้อนุมัติพิจารณาอนุมัติ | H29: =80000*110% -> 88000 | L29: =SUM(D29:H29) -> 88000 | P29: =SUM(L29:M29) -> 88000
A30: 7 | B30: หน้าสำหรับการดู Log การใช้งานระบบ ว่าใครสร้าง แก้ไข หรือลบอะไรไปบ้าง เนื่องจากปัจจุบันยังต้องเข้าไปดูใน Database เท่านั้น จึงพัฒนาหน้า Interface เพิ่มบน Web เพื่อดู Log การใช้งานระบบของ User Role Super Admin หรือ Role อื่นๆที่เกี่ยวข้อง | H30: =80000*110% -> 88000 | L30: =SUM(D30:H30) -> 88000 | P30: =SUM(L30:M30) -> 88000
A31: Add | B31: ดำเนินการสร้าง View ใหม่ 12 view อยู่ที่ IRIN Database และแก้ไข View “Vw_health_current” ให้อยู่ในรูป Structure ใหม่ของ IRIN 1 view เพื่อให้ POWER BI มาใช้ข้อมูล | E31: =ICT_Manday!G57+(8500*3) -> 59500 | H31: =460000*110% -> 506000 | L31: =SUM(D31:H31) -> 565500 | P31: =SUM(L31:M31) -> 565500
A32: 8 | B32: Testing SIT, UAT | K32: =ICT_Manday!F57 -> 68000 | L32: =SUM(D32:I32) -> 0 | M32: =SUM(J32:K32) -> 68000 | P32: =M32 -> 68000
A33: 9 | B33: Training, Document | P33: =8500*3 -> 25500
A35: Group 3 | B35: Technical Consult Team | P35: =P36+P37+P45+P46+P47 -> 212000
A36: 10 | B36: Infrastructure | P36: =SUM(ICT_Manday!R57:S57) -> 59000
A37: 11 | B37: Security Scan | P37: =SUM(P38:P44) -> 127500
B38: Source Code Scan (Coverity and Black Duck) | P38: 8500
B39: Container Image Scan (Trivy) | P39: 8500
B40: Security Scan (OWASP ZAP) | P40: 8500
B41: Quality Scan (SonarQube) | P41: 8500
B42: Automatic Test (Robot framework) | P42: 8500
B43: Performance Test (JMeter) | P43: 8500
B44: Web scan (Acunetix) | P44: =SUM(ICT_Manday!T55:T56) -> 76500
A45: 12 | B45: WSO2 | P45: =SUM(ICT_Manday!N57:O57) -> 0
A46: 13 | B46: CA&A
A47: 14 | B47: Deploy Production | P47: =8500*3 -> 25500

Sheet Man-day_SAP(new)
A1: No. | B1: SAP Function Module | C1: Description | D1: Comment | E1: Comment (Suthat) | F1: ABAP (New Estimate) | G1: SAP PI (New Estimate) | H1: WSO2 (New Estimate) | I1: SAP PM (New Estimate) | J1: BASIS (New Estimate) | K1: SAP Master (New Estimate)
A2: 1 | B2: Modify ZPIPMI032 | C2: PM Notification | D2: การสร้าง Notification ผ่านทาง EIR การ Release Notification ผ่านทาง EIR | E2: 1. add new fields from ZPMPME050 2. Change user status and add long text in Notification 3. รองรับกระบวนการ SCF/MTCO/REWK | F2: 5 | G2: Jr. 3 | H2: Jr. 0.5 | I2: 8 | J2: 2
A3: 2 | B3: Modify ZPIPMI033 | C3: Work Order | D3: การสร้าง/แก้ไข/Release/Close Order ผ่านทาง EIR การ Close Notification ผ่านทาง EIR | E3: 1. add new fields from ZPMPME070 2. Change user status and add long text in Notification 3. รองรับกระบวนการ TECO -> ISCF/MTCO/REWK -> NOCO (BAPI_ALM_NOTIF_CLOSE ซ่อนอยู่ใน ZPIPMI033) | F3: 5 | G3: Jr. 3 | H3: Jr. 0.5 | I3: 8
A4: 3 | B4: ZPIPMI034 | C4: Attach URL | D4: การแนบ URL Link ใน Notification ผ่านทาง EIR การแนบ URL Link ใน Order ผ่านทาง EIR | E4: Reuse ได้
A5: 4 | B5: n/a | C5: SAP Master | D5: SAP Master - Create user + Grant Read only table PM_FL, PM_EQ, PM_NOTI, PM_ORDER, PM_ORDER_OPERATION, PM_LONGTEXT, PM_CLASS, PM_LOCATION (for ECD, EC2, ECP) | E5: ขอ view ที่ EDP Data lake ผบ ติดต่อคุณยิ้ม ธนาภรณ์ น้อยรักษา (560304) THANAPORN.KL@PTTPLC.COM PTT Digital EDP คุณ สุรฤทธิ์ Surarit Chaisuntharanon surarit.c@pttdigital.com
A6: 5 | B6: ZPIPMI045 | C6: PM Time confirmation | D6: การทำ Time confirmation ผ่านทาง EIR (Reuse Pyramid) | E6: สามารถ Reuse ได้ สอบถามหน่วยงาน ผบ ติดต่อคุณยิ้ม ธนาภรณ์ น้อยรักษา (560304) THANAPORN.KL@PTTPLC.COM PTT Digital EDP คุณ สุรฤทธิ์ Surarit Chaisuntharanon surarit.c@pttdigital.com
A7: 6 | B7: New ZPIPMIxxx | C7: Get RAM Matrix | D7: Get Constant table ZBC_ROLLOUT_CONS REPID = ZPMPME050 and ZPMPME070 | E7: เส้น API ใหม่ เพื่อส่งข้อมูล SAP Table ไปให้ IRIN (Table ใน IRIN) ส่ง RAM Matrix จาก SAP ให้ EIR เพื่อที่จะได้มี RAM Matrix ที่เดียว หากมีการเปลี่ยนแปลงก็จะไม่ต้องแก้ไข 2 ที่ | F7: 3 | G7: Sr. 5 | H7: Sr. 0.5 Jr. 1.5 | I7: 2 | M7: 1. RFC Function 2. ต้องการเอา data จาก ZBC_ROLLOUT_CONS ขึ้น EIR | O7: Mode:- 1=GET CONSTANT 2=READ OBJECT 3.=UPDATE OBJECT IT_OBJECT_ID
A8: 7 | B8: New ZPIPMIyyy | C8: Get/Update Attachement link | D8: call FM SO_OBJECT_READ SO_OBJECT_UPDATE | E8: เส้น API ใหม่ Call FM SO_OBJECT_READ SO_OBJECT_UPDATE | F8: 4 | G8: Sr. 5 | H8: Sr. 0.5 Jr. 1.5 | I8: 3 | M8: 3. Mode Read Object 4. Mode Update Object | O8: Mode:- 1=GET CONSTANT 2=READ OBJECT 3.=UPDATE OBJECT IT_OBJECT_ID
A9: 8 | B9: Modify ZPMPME050 | C9: RAM Notification | D9: - Verify data before release (created from ZPIPMI032) - Support testing ZPIPMI032, ZPIPMI033 | E9: แก้ไขใน SAP | F9: 2 | I9: 2
A10: 9 | B10: Modify ZPMPME070 | C10: RAM Order | D10: - Fix case Display mode IW23 --> IW33 - Support testing ZPIPMI032, ZPIPMI033 | E10: แก้ไขใน SAP | F10: 2 | I10: 2
F11: =SUM(F2:F10) -> 21 | G11: =3+3+5+5 -> 16 | H11: 5 | I11: =SUM(I2:I10) -> 25 | J11: =SUM(J2) -> 2 | K11: =SUM(K2:K10) -> 0
C14: SAP PM Sr. | D14: Suthat Lerdarunwatthana
C15: ABAP | D15: Duangjai Channum | E15: รวม | F15: =F11+G11+H11+I11+J11+K11 -> 69
C16: PI Jr. | D16: Supharoek Wutthichaipradit
C17: WSO2 Jr. | D17: Panuwat Paitakaew
C18: WSO2 Sr. | D18: Tawit Choedkiatsakul
C19: Basis Sr. | D19: Kiattisak Banlengchit
C20: SAP Master Sr. | D20: Chonticha Makkata
