Workbook

Sheet Resource
A1: Team Information | F1: Total Manday (Day)
A3: No. | B3: Name | C3: Type | D3: Role | E3: Level | F3: Planned (Day) | G3: Manday Rate (Baht)
A4: 1 | B4: คุณภฤศธร ใต้เวชศาสตร์ | C4: PTT Digital | D4: Project Manager | E4: Senior | F4: =PTTDigital_Manday!D56 -> 38 | H4: 14000 | I4: =F4*H4 -> 532000
A5: 2 | B5: คุณพจนารถ สระหนองห้าง | C5: Outsource | D5: System Analyst | E5: Officer | F5: =PTTDigital_Manday!E56 -> 58 | H5: 8500 | I5: =F5*H5 -> 493000
A6: 3 | B6: คุณณัฐ วัฒนากิจจากุล | C6: Outsource | D6: Business Analyst | E6: Officer | F6: =PTTDigital_Manday!I56 -> 57
A7: 4 | B7: คุณอานนท์ จูงใจ | C7: Outsource | D7: Developer | E7: Officer | F7: =PTTDigital_Manday!F56 -> 144 | H7: 14000 | I7: =F7*H7 -> 2016000
A8: 5 | B8: คุณชนินทร์กานต์ วังคำ | C8: Outsource | D8: Developer | E8: Officer | F8: =PTTDigital_Manday!G56 -> 89
A9: 6 | B9: คุณเมธี อิศรานุวัต | C9: Outsource | D9: Tester | E9: Officer | F9: =PTTDigital_Manday!H56 -> 44
A10: 7 | B10: คุณกรรณิการ์ เพ็งพล | C10: Outsource | D10: Technical Review | E10: Officer | F10: =PTTDigital_Manday!J56 -> 4
A11: 8 | B11: คุณชาญวุฒิ ช่างการ | C11: Outsource | D11: Security | E11: Officer | F11: =PTTDigital_Manday!K56 -> 4
A12: 9 | B12: คุณสถาพร หัสกรรณ์ | C12: Outsource | D12: Infrastructure | E12: Officer | F12: =PTTDigital_Manday!L56 -> 4 | I12: =SUM(I4:I7) -> 3041000
A13: 10 | B13: คุณพัชร มีสวัสดิ์ | C13: Outsource | D13: DevOps | E13: Officer | F13: =PTTDigital_Manday!M56 -> 4
A16: Other Information | C16: Total Amount (Baht)
A17: 1 | B17: Hardware | C17: -
A18: 2 | B18: Software | C18: -
A19: 3 | B19: License | C19: -
A20: 4 | B20: Allowance | C20: -
A21: 5 | B21: ค่าดำเนินโครงการโดยที่ปรึกษาภายนอก | C21: -
A22: 6 | B22: DevOps Service
A24: หมายเหตุ ถ้ามีประเภทค่าใช้จ่ายอื่นๆ เพิ่มเติมใน Project เพิ่ม Row ได้
I26: 1000000
I27: 1190000
H28: Total | I28: 2190000

Sheet Total
B3: Digital Rev (BD Phase) | C3: =PTTDigital_Manday!O60 -> 28000
B4: Digital Rev (Development Phase) | C4: =PTTDigital_Manday!O61 -> 3972000
B5: ค่าเบี้ยเลี้ยง/ค่าเดินทาง | C5: =E13+E19 -> 0
B6: Total | C6: =SUM(C3:C5) -> 4000000
B9: ค่าเดินทาง | C9: จำนวนครั้ง | D9: ครั้งละ | E9: รวมค่าเดินทาง
B10: - | C10: 0 | D10: 2500 | E10: =C10*D10 -> 0
E11: =C11*D11 -> 0
E12: =C12*D12 -> 0
D13: Total | E13: =SUM(E10:E12) -> 0
B15: ค่าเบี้ยเลี้ยง | C15: จำนวนครั้ง | D15: ครั้งละ | E15: รวมค่าเบี้ยเลี้ยง
B16: - | C16: 0 | D16: 600 | E16: =C16*D16 -> 0
B17: - | D17: 600 | E17: =C17*D17 -> 0
B18: - | D18: 600 | E18: =C18*D18 -> 0
D19: Total | E19: =SUM(E16:E18) -> 0
B22: งวดการชำระเงิน PTT >> PTT Digital | C22: % | D22: จำนวนเงิน
B23: งวดที่ 1 : Requirement & Design | C23: 0.4 | D23: =$C$6*C23 -> 1600000
B24: งวดที่ 2 : Phase 1: Test & Go-Live | C24: 0.3 | D24: =$C$6*C24 -> 1200000
B25: งวดที่ 3 : Phase 2: Test & Go-Live | C25: 0.3 | D25: =$C$6*C25 -> 1200000
C26: =SUM(C23:C25) -> 1 | D26: =SUM(D23:D25) -> 4000000

Sheet PTTDigital_Manday
A1: โครงการ ENH-PTTEP-Digital Job Card Phase 5
A2: (ระยะเวลาโครงการ ….270…. วัน) | D2: Sr1 | E2: Of1 | F2: Of1 | G2: Of1 | H2: Of1 | I2: Of1 | J2: Of1 | K2: Of1 | L2: Of1 | M2: Of1 | N2: Of1
A3: Phase | B3: Details | C3: Deliverables | D3: PM | E3: SA | F3: Jr Dev | G3: Jr Dev | H3: Tester | I3: BA | J3: Technical Review | K3: Security | L3: Infrastructure | M3: DevOps | N3: App. Support
D4: Bharitsathorn T. | E4: Potjanart S. | F4: Anon Ju. | G4: Chaninkarn W. | H4: Maytee I. | I4: Nat W. | J4: Kannika P. | K4: Chanvut C. | L4: Sathaporn H. | M4: Patchara M. | N4: Name
A5: Business Development | B5: Gather Initial Requirements | C5: Proposal | D5: 2
B6: Create Proposal & Project Plan
B7: Vendor Selection
B8: Impact analyst
A9: Project Planning | B9: Kick-Off Meeting | D9: 6
B10: Create Project Plan, Other Plans and Integrate to Project Plan
B11: Monitoring
B12: Progress Report
B13: Prepare and setup Development Environment
A14: Requirement Development | B14: Get Requirement | D14: 6 | E14: 5 | I14: 8
B15: Create Business Blueprint
B16: Peer Review Requirement Specification
B17: Confirm Requirement Specification with Customer
B18: Sign off Requirement Specification
B19: Create Baseline for Design(CM)
A20: Design | B20: Peer Review Design Specification | C20: Sign-Off Requirement Specification | D20: 2 | E20: 5 | I20: 2
B21: Clarify Design
B22: Sign off Design Specification
B23: Peer Review Technical Specification
A24: Develop & Unit Test | B24: Development & Unit Test
B25: 1.Build & Test Crane load test Form | D25: 17 | E25: 7 | F25: 17 | G25: 5 | H25: 9 | I25: 6
B27: 2.Build & Test Crane Pull Test Form | E27: 7 | F27: 11 | G27: 10 | H27: 9 | I27: 6
B29: 3.Build & Test OverHead Line Form | E29: 9 | F29: 16 | G29: 10 | H29: 9 | I29: 6
B31: 4. Build & Test Enh_Existing_Funtion_DJC#5 WHP, Transmitter, PSV | E31: 18 | F31: 100 | G31: 64 | H31: 17 | I31: 29
A33: SIT & UAT | B33: Testing | C33: Sign-Off UAT
B34: Peer Review Software Implementation & Unit Test
B35: Create Test Scenario & Test Script
B36: System Integration Test (SIT) | D36: 1 | E36: 1
B37: User Acceptance Test (UAT) | D37: 1 | E37: 1
B38: Sign-Off UAT
B39: Perform Security Test
B40: EA Process
B41: Create Baseline for Final Preparation
A43: Final Preparation | B43: Develop Deployment Plan & Readiness Checklist | C43: Production Deployment | D43: 2 | E43: 5 | J43: 2 | K43: 2 | L43: 2 | M43: 2
B44: Create release documents
B45: Prepare Training Material / User Manual
...

Sheet Travel Cost
B4: ค่าเดินทาง | C4: จำนวนครั้งที่ไป | F4: ราคา | H4: จำนวนหน่วย | I4: จำนวนการใช้งาน | J4: รวม
C5: Requirement & Design | D5: 0 | F5: ค่าเดินทาง | G5: 2500 | H5: 0 | I5: 0 | J5: =G5*H5*I5 -> 0
C6: UAT | D6: 0 | F6: ค่าที่พัก | G6: 2500 | H6: 0 | I6: 0 | J6: =G6*H6*I6 -> 0
C7: Go-Live & Training | F7: ค่าเบี้ยเลี้ยง | G7: 600 | H7: 0 | I7: 0 | J7: =G7*H7*I7 -> 0
C8: Total | D8: =SUM(D5:D7) -> 0 | I8: รวมค่าเดินทาง | J8: =SUM(J5:J7) -> 0

Sheet Project Timeline
A1: Project timeline: 11 months periods | C1: 46204 | G1: 46235 | K1: 46266 | O1: 46296 | S1: 46327 | W1: 46357 | AA1: 46388 | AE1: 46419 | AI1: 46447 | AM1: 46478 | AQ1: 46508 | AU1: 46539
A2: No | B2: Task | C2: w1 | D2: w2 | E2: w3 | F2: w4 | G2: w1 | H2: w2 | I2: w3 | J2: w4 | K2: w1 | L2: w2 | M2: w3 | N2: w4 | O2: w1 | P2: w2 | Q2: w3 | R2: w4 | S2: w1 | T2: w2 | U2: w3 | V2: w4 | W2: w1 | X2: w2 | Y2: w3 | Z2: w4 | AA2: w1 | AB2: w2 | AC2: w3 | AD2: w4 | AE2: w1 | AF2: w2 | AG2: w3 | AH2: w4 | AI2: w1 | AJ2: w2 | AK2: w3 | AL2: w4 | AM2: w1 | AN2: w2 | AO2: w3 | AP2: w4 | AQ2: w1 | AR2: w2 | AS2: w3 | AT2: w4 | AU2: w1 | AV2: w2 | AW2: w3 | AX2: w4
A3: 1 | B3: Project Preparation
A4: 2 | B4: Project Kick-off
A5: 3 | B5: Gather Requirement
A6: 4 | B6: Analysis & Design
A7: 5 | B7: Build & Test
A8: 6 | B8: SIT | P8: SIT#1 | AM8: SIT#2
A9: 7 | B9: UAT | S9: UAT#1 | AO9: UAT#2
A10: 8 | B10: Deliver Project Document | U10: Training#1 | AQ10: Training#2
A11: 9 | B11: Final Preparation & Production Deployment | U11: Deploy#1 | AQ11: Deploy#2
A12: 10 | B12: Regression Test | W12: REG Test
A13: 11 | B13: Go-live | U13: Go-Live#1 | AQ13: Go-Live#2
A14: 12 | B14: Support after Go-live | AS14: Support after Go-live
B16: : งวดส่งมอบงาน
