Workbook
Name _Toc184826375: 'Vendor Cost'!$J$26
Name _Toc184826376: 'Vendor Cost'!$J$49
Name _Toc184826377: 'Vendor Cost'!$J$39
Name PriceRole: #REF!
Name Role: #REF!

Sheet Total
B3: Digital Cost (BD Phase) | C3: =Digital_Manday!I45 -> 17000
B4: Digital Cost (Development Phase) | C4: =Digital_Manday!I46 -> 586500
B5: Vendor Cost + 10 % | C5: ='Vendor Cost'!E13*110% -> 1583450
B6: Total | C6: =SUM(C3:C5) -> 2186950
B8: ค่าเดินทาง (PM) | D8: วัน
B9: ค่าเบี้ยเลี้ยง (PM) | D9: วัน
B10: ค่าเดินทาง (BA) | D10: วัน
B11: ค่าเบี้ยเลี้ยง (BA) | D11: วัน
B12: ค่าที่พัก BA | C12: 0 | D12: วัน
B15: ค่าเดินทาง PM | C15: =(C8*2500) -> 0
B16: ค่าเบี้ยเลี้ยง PM | C16: =(C9*600) -> 0
B17: ค่าเดินทาง BA | C17: =(C10*2500) -> 0
B18: ค่าเบี้ยเลี้ยง BA | C18: =(C11*600) -> 0
A19: ที่พัก | B19: PM + BA | C19: =C12*2500 -> 0
B20: รวมค่าเดินทางและเบี้ยเลี้ยง | C20: =SUM(C15:C19) -> 0
B22: Grand Total | C22: =C6+C20 -> 2186950
B23: Estimated Budget #1 | C23: 2200000
B27: PTT Paid (PTT-->PTT Digital)
B28: 1 | C28: =$C$22*B28 -> 2186950
B29: 0 | C29: =$C$22*B29 -> 0
B30: 0 | C30: =$C$22*B30 -> 0
B31: PTT Digital Paid (PTT Digital-->Vendor)
B32: 1 | C32: ='Vendor Cost'!$E$13*Total!B32 -> 1439500
B33: 0 | C33: ='Vendor Cost'!$E$13*Total!B33 -> 0
B35: Vendor Ratio | C35: =C32*100/C28 -> 65.822264
B36: PTT Digital Ratio | C36: =100-C35 -> 34.177736

Sheet Digital_Manday
A1: โครงการ ENH-PTT Tank eMOC 2569
A2: (ระยะเวลาโครงการ 160วัน) | E2: Nantaporn P. | F2: Nantaporn P. | G2: Nantaporn P.
A3: Phase | B3: Details | C3: Deliverables | D3: PM-Nantaporn P. | E3: BA | F3: SA | G3: Tester | H3: Sharepoint Admin
D4: Jr. | E4: Jr. | F4: Jr. | G4: Jr. | H4: ATA/C
A5: Business Development | B5: Gather Initial Requirements | C5: Proposal, TOR | D5: 2
B6: Vendor Selection
B7: Impact analyst | D7: 2
A9: Project Planning | B9: Kick-Off Meeting | D9: 0.5 | E9: 0.5
B10: Create Project Plan, Other Plans and Integrate to Project Plan | D10: 1 | E10: 0.5
B11: WBS & Risk Management | D11: 1 | E11: 1
A12: Requirement Development | B12: Requirement Gathering | D12: 2 | E12: 2
B13: Confirm Requirement Specification with Customer | D13: 1 | E13: 1
B14: Sign off Requirement Specification
A15: Design | B15: Analysis & Create Design Specification | C15: Sign-Off Requirement & Design Specification | D15: 0.5 | F15: 2
B16: Peer Review Design Specification | D16: 1 | F16: 1
B17: Clarify Design with Customer | D17: 1 | E17: 1
B18: Create Test Senario | D18: 0.5 | G18: 1
B19: Confirm Test Senario with Customer | D19: 1 | E19: 1
B20: Sign off Design Specification | D20: 0.5
B21: Prepare and setup Test Environment | D21: 0.5 | F21: 1
A22: Development | B22: Software Implementation & Unit Test | D22: 1 | G22: 2 | H22: 3
B23: Develop Unit test script | D23: 1 | G23: 2
B24: System Integration Test | D24: 1 | G24: 1
B25: User Acceptance Test (UAT) | D25: 3 | G25: 3
B26: Sign-Off UAT | D26: 1
B27: Source Code Scan (Coverity and Black Duck) | D27: เป็น Sharepoint ซี่งเป็น Software package จึงไม่ต้องดำเนินการใน Task นี้
B28: Web Scan (Acunetix) | D28: เป็น Sharepoint เครื่อง Pool ไม่สามารถดำเนินการได้
B29: Create Baseline for Final Preparation | D29: 0.5 | F29: 0.5
A30: Final Preparation | B30: Develop Deployment Plan & Readiness Checklist | D30: 1 | F30: 1
B31: Go-live | D31: 1 | F31: 1
B32: Create release documents | D32: 0.5 | F32: 1
B33: Prepare and conduct Training | D33: 0.5 | E33: 1
B34: Prepare and perform Data migration/conversion | D34: 0.5 | F34: 1
B35: Prepare and setup Production Environment | D35: 0.5 | F35: 1
B36: Technical Training | D36: 0.5 | F36: 0.5
A37: Project Closure | B37: Go-live Sign off | C37: Sign-Off GO Live | D37: 0.5
B38: Support After Go-live 1 Month | D38: 2 | E38: 2
B39: Evaluate supplier/vendor
B40: Survey Customer Satisfaction
B41: Create Project closure report and Completion sign-off | D41: 1 | E41: 1
...

Sheet Vendor Cost
C2: โครงการ ENH-PTT Tank-eMOC
C3: Vendor : บริษัท ธาลาโม จำกัด
C5: Order | D5: Description | E5: Cost
C6: 1 | D6: ค่าปรับปรุงระบบเว็บ MOC | E6: 1439500 | F6: 0.3 | G6: =E6*F6 -> 431850 | H6: Design
F7: 0.3 | G7: =E6*F7 -> 431850 | H7: Test
F8: 0.4 | G8: =E6*F8 -> 575800 | H8: Go Live
D11: Total | E11: =SUM(E6:E10) -> 1439500
D12: Discount
D13: Grand Total | E13: =E11-E12 -> 1439500
D14: ราคานี้ยังไม่รวม Vat 7%
D17: Proposal-07-PTTTank-eMOC-2026.pdf

Sheet Project Timeline
C1: 46204 | G1: 46235 | K1: 46266 | O1: 46296 | S1: 46327 | W1: 46357
B3: Project Activity | C3: M1 | G3: M2 | K3: M3 | O3: M4 | S3: M5 | W3: M6
C4: W1 | D4: W2 | E4: W3 | F4: W4 | G4: W1 | H4: W2 | I4: W3 | J4: W4 | K4: W1 | L4: W2 | M4: W3 | N4: W4 | O4: W1 | P4: W2 | Q4: W3 | R4: W4 | S4: W1 | T4: W2 | U4: W3 | V4: W4 | W4: W1 | X4: W2 | Y4: W3 | Z4: W4
B5: PO&PR , Project Planing
B6: Requirement Gathering
B7: - Requirement Gathering
B8: - Business Requirement Document
B9: Design
B10: - Detailed Design
B11: - Detailed Design Document
B12: - Design Sign-off
B13: Software Development
B14: - Web Development
B15: Testing
B16: - System Integration Test
... B21: - Go-Live Sign-off
K23: 70 | W23: 160
K24: 0.5 | W24: 0.5
K25: Design phase | W25: Test & Go live Phase

Sheet Scope of Work
A1: ENH-PTT Tank eMOC 2569
A2: Proposal ID | B2: หัวข้อ | C2: Require
A3: 1 | B3: ปรับปรุง Part review โดยเพิ่ม function การ assignment implementor จาก รวก. หรือ รปค. หลังจาก MOC ได้รับการอนุมัติให้ดำเนินการใน Part review | C3: Y | D3: Business Requirement
A4: 2 | B4: เพิ่มความถี่ในการส่ง e-mail แจ้งเตือนการอนุมัติ โดยให้แจ้งเตือนทุกวันจนกว่าจะอนุมัติ | C4: Y | D4: Business Requirement
A5: 3 | B5: แก้ไข Function การอนุมัติให้ Reviewer สามารถคลิ๊กอนุมัติได้โดยไม่ติด Feedback | C5: Y | D5: Business Requirement
A6: 4 | B6: เพิ่ม Authorize ให้ Admin สามารถแก้ไขข้อความหรือเพิ่มไฟล์แนบในแต่ละ Step ทั้งใน part ปัจจุบันและรวมถึง part ที่ผ่านมาแล้ว | C6: Y | D6: Business Requirement
A7: 5 | B7: กำหนด ผจ.ปร. และ ผจ.ปค. เป็น Area manager เพื่อพิจารณาอนุมัติ MOC ที่ทำเสร็จแล้ว ก่อนเริ่ม Start up ใน Part Implementation | C7: Y | D7: Business Requirement
A8: 6 | B8: บล็อก Function override ให้ไม่สามารถกรอกข้อมูลได้ แต่ยังคงข้อมูลเดิมในระบบ | C8: Y | D8: Business Requirement
A9: 7 | B9: เพิ่ม e-mail แจ้งเตือน initiator หลังจากอนุมัติ Part review, ก่อนเริ่ม Start up และเมื่อจบ Close out | C9: Y | D9: Business Requirement
A10: 8 | B10: ลบ item แนบเอกสารใน part implement และ close out ที่ไม่จำเป็นออก | C10: Y | D10: Business Requirement
A11: 9 | B11: ปรับเปลี่ยนชื่อ Role: MOC Owner เป็น MOC Engineer ครอบคลุมทั้ง Plant change และ Maintenance change | C11: Y | D11: Business Requirement
A12: 10 | B12: ใน Part Implement เพิ่มขั้นตอนให้ ผจ.ส่วน ของ Implementer เลือก Implementer ได้ | C12: Y | D12: Business Requirement
A17: Out of Scope
A19: 1 | B19: งานอื่นใดที่ไม่ได้ระบุอยู่ในหัวข้อที่ 2 “Areas in scope” ให้ถือเป็นงานที่อยู่นอกเหนือขอบเขตของข้อเสนอโครงการนี้ งานที่ระบุต่อไปนี้เป็นงานที่อยู่นอกเหนือขอบเขตของข้อเสนอโครงการนี้
A20: 2 | B20: การแก้ไขปัญหาระบบอื่น ๆ ที่เกี่ยวข้อง เช่น ปัญหาของระบบงาน Active Directory, Mail server, Reverse Proxy Server เป็นต้น
A21: 3 | B21: การแก้ไขปัญหา Hardware และ Network
A22: 4 | B22: การแก้ไขปัญหาที่เกิดจาก Bugs ของ Software เช่น SharePoint, SQL Server, Windows Server เป็นต้น
A23: 5 | B23: การนำเข้าข้อมูล Content (Content Authoring) เช่น กรอกหรือนำเข้าข้อมูล Members เป็นต้น
A24: 6 | B24: การทำ Content Migration, Data Cleansing
A25: 7 | B25: Developer license ของเครื่องมือที่ใช้ในการพัฒนา ได้แก่ Kendo UI
A26: 8 | B26: การตั้งค่า Network เพื่อให้ผู้ใช้งานบริษัทในกลุ่ม ปตท. ให้สามารถเข้าใช้งานระบบงานได้
A27: 9 | B27: การเข้าสู่กระบวนการ DevOps Process
A28: 10 | B28: การ Scan และแก้ไข Coverity, BlackDucks, Acunetix หรือ Security Scan อื่น ๆ ทั้งในช่วง Implementation และช่วง Warranty
A29: 11 | B29: ฟังก์ชันการให้ Admin สามารถถอย Part ได้
A30: 12 | B30: ไม่มีการทำ Knowledge Transfer to PTT Digital
