Workbook
Name Alpha: [1]Actual!#REF!
Name LstLevel: '[2]999_MSRP'!$A$3:$A$10
Name LstStaffs: '[2]999_Loaded Rate 2016-Q1'!$F$2:$F$468
Name Peak: [1]Actual!#REF!
Name Time0: [1]Actual!#REF!
Name Time1: [1]Plan!#REF!
Name Time2: [1]Plan!#REF!
Name Value1: [1]Plan!#REF!
Name Value2: [1]Plan!#REF!

Sheet Resource
A1: Team Information | F1: Total Manday (Day)
A3: No. | B3: Name | C3: Type | D3: Role | E3: Level | F3: Planned (Day) | G3: Manday Rate (Baht)
A4: 1 | B4: Kongdech Hisavanich | C4: Outsource | D4: PM | E4: Senior Officer | F4: 32 | G4: 14000 | H4: 14000 | I4: =F4*H4 -> 448000
A5: 2 | B5: Sasivimol Chinudomsuksakul | C5: Outsource | D5: BA | E5: Senior Officer | F5: 46 | G5: 14000 | H5: 14000 | I5: =F5*H5 -> 644000
A6: 3 | B6: Kamonwan Oilkham | C6: Outsource | D6: BA | E6: Officer | F6: 61 | G6: 8500 | H6: 8500 | I6: =F6*H6 -> 518500
A7: 4 | B7: Eakarin Pintafai | C7: Outsource | D7: Developer | E7: Officer | F7: 25 | G7: 8500 | H7: 8500 | I7: =F7*H7 -> 212500
A8: 5 | B8: Wuttipong Inpalud | C8: Outsource | D8: Developer | E8: Officer | F8: 15 | G8: 8500 | H8: 8500 | I8: =F8*H8 -> 127500
A9: 6 | B9: Natamon Jongbandan | C9: Outsource | D9: QA Team | E9: Officer | F9: 3 | G9: 8500 | H9: 8500 | I9: =F9*H9 -> 25500
I10: =F10*H10 -> 0
I11: =SUM(I4:I10) -> 1976000
A12: Other Information | C12: Total Amount (Baht)
A13: 1 | B13: Hardware | C13: -
A14: 2 | B14: Software | C14: -
A15: 3 | B15: License | C15: -
A16: 4 | B16: Allowance | C16: -
A17: 5 | B17: ค่าดำเนินโครงการโดยที่ปรึกษาภายนอก (IBS Software) | C17: -
A18: 6 | B18: DevOps Service
A20: หมายเหตุ ถ้ามีประเภทค่าใช้จ่ายอื่นๆ เพิ่มเติมใน Project เพิ่ม Row ได้
H24: Total

Sheet Total
B3: Digital Rev (Project Cost) | C3: =PTTDigital_Manday!L77 -> 1976000
B4: ค่าเบี้ยเลี้ยง/ค่าเดินทาง | C4: =E13+E19 -> 0
B5: Vendor Cost | C5: ='Vendor Cost'!E12 -> 0
B6: Total | C6: =SUM(C3:C5) -> 1976000
B9: ค่าเดินทาง | C9: จำนวนครั้ง | D9: ครั้งละ | E9: รวมค่าเดินทาง
B10: Location A | E10: =C10*D10 -> 0
B11: Location B | E11: =C11*D11 -> 0
B12: Location C | E12: =C12*D12 -> 0
D13: Total | E13: =SUM(E10:E12) -> 0
B15: ค่าเบี้ยเลี้ยง | C15: จำนวนครั้ง | D15: ครั้งละ | E15: รวมค่าเบี้ยเลี้ยง
B16: MR A | D16: 600 | E16: =C16*D16 -> 0
B17: MR B | D17: 600 | E17: =C17*D17 -> 0
B18: MR C | D18: 600 | E18: =C18*D18 -> 0
D19: Total | E19: =SUM(E16:E18) -> 0
B22: งวดการชำระเงิน PTTEP >> PTT Digital | C22: % | D22: จำนวนเงิน | G22: Digital Cost + Vendor | H22: =C6+E13+E19 -> 1976000
B23: งวดที่ 1 : Kick off | C23: 0.2 | D23: =$C$6*C23 -> 395200 | G23: Margin | H23: =H22-(C3+'Vendor Cost'!E12) -> 0
B24: งวดที่ 2 : Requirement Gathering | C24: 0.3 | D24: =$C$6*C24 -> 592800
B25: งวดที่ 3 : User Acceptance Test | C25: 0.3 | D25: =$C$6*C25 -> 592800 | G25: % Margin | H25: =H23/H22 -> 0
B26: งวดที่ 4 : Go-live | C26: 0.2 | D26: =$C$6*C26 -> 395200
C30: =SUM(C23:C29) -> 1 | D30: =SUM(D23:D29) -> 1976000
B32: งวดการชำระเงิน PTT DIGITAL >> Vendor | C32: % | D32: จำนวนเงิน
B33: งวดที่ 1 : Requirement & Design | C33: 0.4 | D33: ='Vendor Cost'!$E$12*Total!C33 -> 0
B34: งวดที่ 2 : Golive # 1 | C34: 0.3 | D34: ='Vendor Cost'!$E$12*Total!C34 -> 0
B35: งวดที่ 3 : Golive # 2 | C35: 0.3 | D35: ='Vendor Cost'!$E$12*Total!C35 -> 0
C36: =SUM(C33:C35) -> 1 | D36: =SUM(D33:D35) -> 0

Sheet PTTDigital_Manday
A1: Project : PJR-PTTEP-Discrepancy and Write-off System (DiW) for Corporate
A2: (ระยะเวลาโครงการ 280 วัน) | D2: Sr1 | E2: Sr1 | F2: Of1 | G2: Of1 | H2: Of1 | I2: Of1 | J2: Sr1 | K2: Of1
A3: Phase | B3: Details | C3: Deliverables | D3: PM | E3: BA | F3: BA | G3: Developer | H3: Developer | I3: QA | J3: Tech. Review | K3: App. Support
D4: Kongdech H. | E4: Sasivimol C | F4: Kamonwan O | G4: Eakkarin P | H4: Wuttipong | I4: Natamon J | J4: Name | K4: Name
A5: Project Planning | B5: Pre-pare proposal & procument process | C5: Proposal, Kick-off Presentation, Project Plan | D5: 5 | E5: 2
B6: Project Assessment and Planing | D6: 3 | E6: 6
B7: Project Kick-off | D7: 1 | E7: 2
A8: Implement, Testing and Deployment forPhase 1A | B8: Weekly progress and Issue management (11 months) - Weekly Progress report - Internal progress tracking - Issue log management | C8: Weekly report | D8: 20 | E8: 2
A9: Requirement Gethering and Design | B9: DDR – Damage discrepancy report | C9: SRS & FSD Document, SRS & FSD Sign-Off
B10: - Intergrattion Module with GCP | E10: 0.5 | F10: 1
B11: - Group,Roles and Authorization by country/asset/plant | E11: 0.5 | F11: 1
B12: - Table, backend screen, Logic | E12: 0.5 | F12: 1
B13: - Workflow | E13: 0.5 | F13: 1
B14: - Email Notification | E14: 0.5 | F14: 0.5
B15: - Generate PDF | E15: 0.5 | F15: 0.5
B16: - Portal form (Update solution) | E16: 0.5 | F16: 0.5
B17: - Dashboard | E17: 0.5 | F17: 0.5
B18: - Schedule job (reminder email) | E18: 0.5 | F18: 0.5
B19: Inteface to GCP
B20: - Settle solution with GCP | E20: 1 | F20: 2
B21: - Intergrate with GCP | E21: 1 | F21: 2
B22: - Prepare data object | E22: 0.5 | F22: 1
B23: - Logic | E23: 0.5 | F23: 1
B24: Prepare document and confirm
B25: Prepare SRS and confirmation | E25: 2 | F25: 3
B26: System design with DEV team | E26: 1.5 | F26: 1.5
B27: Prepare FSD and confirmation | E27: 2 | F27: 3
B28: Milestone 2/4 : SRS & FSD Sign-Off | D28: 0.5
A29: Implement, Testing and Deployment | B29: Sprint 1 - DDR – Damage discrepancy report
B30: Solution development & Unit Test
B31: - Intergrate data from GCP | G31: 3
B32: - Group,Roles and Authorization by country/asset/plant | G32: 2
B33: - Table, backend screen, Logic | G33: 4
B34: - Workflow | G34: 4
B35: - Email Notification | G35: 2
B36: - Generate PDF | G36: 2
B37: - Portal form (Update solution) | G37: 2
B38: - Dashboard | G38: 2
B39: - Schedule job (reminder email) | G39: 2
B40: Prepare Sprint demo and SIT Script
...

Sheet Sheet1
A1: Project : PJR-PTTEP-Discrepancy and Write-off System (DiW) for Corporate
A2: (ระยะเวลาโครงการ 280 วัน) | D2: Sr1 | E2: Sr1 | F2: Sr1 | G2: Sr1 | H2: Sr1 | I2: Sr1 | J2: Of1 | K2: Sr1 | L2: Of1
A3: Phase | B3: Details | C3: Deliverables | D3: PM | E3: BA | F3: SA | G3: SA | H3: Developer | I3: Developer | J3: QA | K3: Tech. Review | L3: App. Support
D4: Kongdech H. | E4: Sasivimol C | F4: Penpitcha O | G4: Kamonwan O | H4: Eakkarin P | I4: Wuttipong | J4: Natamon J | K4: Name | L4: Name
A5: Project Planning | B5: Pre-pare proposal & procument process | C5: Proposal, Kick-off Presentation, Project Plan | D5: 4 | E5: 4
B6: Project Assessment and Planing | D6: 6 | E6: 6 | F6: 2 | G6: 2
B7: Project Kick-off | D7: 1 | E7: 2 | F7: 0.5 | G7: 0.5
A8: Implement, Testing and Deployment forPhase 1A | B8: Weekly progress and Issue management (14 months) - Weekly Progress report - Internal progress tracking - Issue log management | C8: Weekly report | D8: 20 | E8: 4
B9: Sprint 1 - DDR – Damage discrepancy report
B10: Gather requirement/ Design
B11: - Intergrate data from GCP | E11: 2 | G11: 4
B12: - Group,Roles and Authorization by country/asset/plant | E12: 1 | G12: 2
B13: - Table, backend screen, Logic | E13: 2 | G13: 4
B14: - Workflow | E14: 2 | G14: 4
B15: - Email Notification | E15: 2 | G15: 3
B16: - Generate PDF | E16: 1 | G16: 2
B17: - Portal form (Update solution) | E17: 2 | G17: 4
B18: - Dashboard | E18: 1 | G18: 2
B19: - Schedule job (reminder email) | E19: 1 | G19: 2
B20: Solution development & Unit Test
B21: - Intergrate data from GCP | H21: 3
B22: - Group,Roles and Authorization by country/asset/plant | H22: 2
B23: - Table, backend screen, Logic | H23: 5
B24: - Workflow | H24: 4
B25: - Email Notification | I25: 2
B26: - Generate PDF | I26: 4
B27: - Portal form (Update solution) | I27: 5
B28: - Dashboard | I28: 2
B29: - Schedule job (reminder email) | I29: 2
B30: Prepare Sprint demo and SIT Script
B31: - Prepare SIT script | E31: 1 | F31: 4
B32: - Excute SIT | E32: 1.5 | F32: 5
B33: - Prepare demo presentation (with UAT senario) | E33: 1 | F33: 3
B34: UAT assistance and Product Backlog update
B35: - Perform demo feature and Execute UAT | E35: 2 | F35: 2 | G35: 2 | H35: 1 | I35: 1
B36: - Update and Summarize Product backlog | F36: 0.5 | G36: 0.5
B37: Sprint 2 - IDR – Inventory discrepancy report
B38: Gather requirement/ Design
B39: - Intergrate data from GCP | E39: 1 | F39: 3
B40: - Group,Roles and Authorization by country/asset/plant | E40: 1 | F40: 2
...

Sheet Vendor Cost
C2: Project : -
C3: Vendor : -
C5: Order | D5: Description | E5: Cost
C6: 1 | D6: Implement Cost | E6: -
D10: Total | E10: =SUM(E6:E9) -> 0
D11: Discount
D12: Grand Total | E12: =E10-E11 -> 0
D14: ** ราคานี้ยังไม่รวม Vat 7% **

Sheet Plan
C1: 2025 | L1: 2026
A2: Project : Discrepancy and Write off System (DiW) for Malausia | C2: June | G2: July | L2: Month 01 | P2: Month 02 | T2: Month 03 | Y2: Month 01 | AC2: Month 02 | AG2: Month 03 | AK2: Month 04 | AP2: Month 05 | AT2: Month 06 | AY2: Month 7 | BC2: Month 11 | BG2: Month 12
C3: W1 | D3: W2 | E3: W3 | F3: W4 | G3: W1 | H3: W2 | I3: W3 | J3: W4 | K3: W5 | L3: W1 | M3: W2 | N3: W3 | O3: W4 | P3: W1 | Q3: W2 | R3: W3 | S3: W4 | T3: W1 | U3: W2 | V3: W3 | W3: W4 | X3: W5 | Y3: W1 | Z3: W2 | AA3: W3 | AB3: W4 | AC3: W1 | AD3: W2 | AE3: W3 | AF3: W4 | AG3: W1 | AH3: W2 | AI3: W3 | AJ3: W4 | AK3: W1 | AL3: W2 | AM3: W3 | AN3: W4 | AO3: W5 | AP3: W1 | AQ3: W2 | AR3: W3 | AS3: W4 | AT3: W1 | AU3: W2 | AV3: W3 | AW3: W4 | AX3: W5 | AY3: W1 | AZ3: W2 | BA3: W3 | BB3: W4 | BC3: W1 | BD3: W2 | BE3: W3 | BF3: W4 | BG3: W1 | BH3: W2 | BI3: W3 | BJ3: W4 | BK3: W5
A4: Phase I : Project Management
A5: 1.1 | B5: Prepare proposal & procument process | AA5: 3 | AB5: 3
A6: 1.2 | B6: Project assessment and planning | AA6: 3
A7: 1.3 | B7: Project Kick-off | AC7: 3
A8: 1.4 | B8: Milestone 1/4 : SRS & FSD Sign-Off | AC8: 3
A9: 1.5 | B9: Weekly progress update
A10: Phase II : Requirement Gethering and Design
A11: 2.1 | B11: DDR Gather requirement/ Design | AC11: 3 | AD11: 3
A12: 2.2 | B12: Inteface to GCP(DiW -> GCP) Gather requirement/ Design | AD12: 3
A13: 2.3 | B13: Prepare SRS and confirmation
A14: 2.4 | B14: System design with DEV team
A15: 2.5 | B15: Prepare FSD and confirmation
A16: 2.6 | B16: Milestone 2/4 : SRS & FSD Sign-Off
A17: Phase III : Implement
A18: 3.1 | B18: Sprint 1 - DDR – Damage discrepancy report
A19: 3.1.1 | B19: Solution development and UT/RT/SIT
A20: 3.1.2 | B20: Sprint demo and pre-pare UAT
A21: 3.1.3 | B21: UAT assistance and Product Backlog update
A22: 3.2 | B22: Sprint 2 - Inteface to GCP
A23: 3.2.1 | B23: Solution development and UT/RT/SIT | AH23: 3 | AI23: 3 | AJ23: 3
A24: 3.2.2 | B24: Sprint demo and pre-pare UAT | AJ24: 3 | AK24: 3 | AL24: 3
A25: 3.2.3 | B25: UAT assistance and Product Backlog update | AM25: 3 | AN25: 3
A26: Phase IV : SIT & UAT with SHANA
A27: 4.1 | B27: RT/SIT Component | AD27: 3 | AE27: 3 | AF27: 3
A28: 4.2 | B28: Performance Test | AG28: 3 | AH28: 3 | AI28: 3 | AJ28: 3 | AK28: 3
A29: 4.3 | B29: UAT | AL29: 3 | AM29: 3 | AN29: 3
A30: 4.4 | B30: Product Backlog update | AL30: 3 | AM30: 3 | AN30: 3
A31: Phase V : Training & Final UAT
A32: 5.1 | B32: Summary UAT Script & Review | AO32: 3 | AP32: 3
A33: 5.2 | B33: Deliver all backlog | AP33: 3 | AQ33: 3
A34: 5.3 | B34: Milestone 3/4 : UAT Sign-Off | AQ34: 3
A35: 5.4 | B35: Develop User guides, Admin Guides | AQ35: 3 | AR35: 3
A36: 5.5 | B36: Train the Trainer | AR36: 3 | AS36: 3 | AT36: 3
A37: Phase VI : Deployment
A38: 6.1 | B38: QA Process | AS38: 3 | AT38: 3
A39: 5.2 | B39: Go-live Comunication & preparation | AT39: 3 | AU39: 3 | AV39: 3
A40: 6.3 | B40: Go-Live | AV40: 3
...

Sheet Vendor MD
B1: PTTEP FaFE Phase 4 | C1: Resource | D1: Summary | E1: Solution Consultant (EmpowerAll) | F1: Technical Consultant (Empower All) | G1: Junior Technical Consultant (Empower All)
B2: Name | E2: TBA | F2: TBA | G2: TBA
B3: Rate | E3: 30240 | F3: 22680 | G3: 12060
B4: Initiate Stage
B5: Gathering Requirement
B6: Research Solution
B7: Business Development Stage
B8: Prepare Team member project
B9: Define Scope of work
B10: Prepare Stage
B11: Pre-pare proposal & procument process
B12: Project Assessment and Planing
B13: Project Kick-off
B14: Create Stage
B15: Sprint 1 - Standalone module | E15: =SUM(E16:E18) -> 0 | F15: =SUM(F16:F18) -> 0 | G15: =SUM(G16:G18) -> 0
B16: Gather requirement/ Design
B17: Solution development & Unit Test
B18: Sprint demo, SIT/UAT assistance and Product Backlog update
B19: Sprint 2 - Memo module | E19: =SUM(E20:E23) -> 0 | F19: =SUM(F20:F23) -> 0 | G19: =SUM(G20:G23) -> 0
B20: Gather requirement/ Design
B21: Develop issue from previous backlog
B22: Solution development & Unit Test
B23: Sprint demo, SIT/UAT assistance and Product Backlog update
B24: Sprint 3 - TEPM Expansion | E24: =SUM(E25:E28) -> 0 | F24: =SUM(F25:F28) -> 0 | G24: =SUM(G25:G28) -> 0
B25: Gather requirement/ Design
B26: Develop sprint backlog
B27: Solution development & Unit Test
B28: Sprint demo, SIT/UAT assistance and Product Backlog update
B29: Sprint 4 - RFS module | E29: =SUM(E30:E33) -> 0 | F29: =SUM(F30:F33) -> 0 | G29: =SUM(G30:G33) -> 0
B30: Gather requirement/ Design
B31: Develop issue from previous backlog
B32: Solution development & Unit Test
B33: Sprint demo, SIT/UAT assistance and Product Backlog update
B34: Sprint 5 - Data bridging | E34: =SUM(E35:E39) -> 0 | F34: =SUM(F35:F39) -> 0 | G34: =SUM(G35:G39) -> 0
B35: SAP Integration RO, Contract, Enhance PO/SO
B36: Gather requirement/ Design
B37: Develop sprint backlog
B38: Solution development & Unit Test
B39: Sprint demo, SIT/UAT assistance and Product Backlog update
B40: Sprint 6 - GRO module | E40: =SUM(E41:E44) -> 0 | F40: =SUM(F41:F44) -> 0 | G40: =SUM(G41:G44) -> 0
...
