Workbook
Name LstLevel: '[1]999_MSRP'!$A$3:$A$10
Name LstStaffs: '[1]999_Loaded Rate 2016-Q1'!$F$2:$F$468

Sheet Resource
A1: Team Information | F1: Total Manday (Day)
A3: No. | B3: Name | C3: Type | D3: Role | E3: Level | F3: Planned (Day) | G3: Manday Rate (Baht)
A4: 1 | B4: Wannaporn Jaemklam | C4: Outsource | D4: PM/BA/Tester | E4: Senior Officer | F4: 30 | G4: 14000 | H4: 14000 | I4: =F4*H4 -> 420000
A5: 2 | B5: Wissanu Tangtrongkijwong | C5: Outsource | D5: Developer | E5: Senior Officer | F5: 30 | G5: 14000 | H5: 8500 | I5: =F5*H5 -> 255000
A6: 3 | B6: Niti Wisatchanam | C6: Outsource | D6: Developer | E6: Officer | F6: 37 | G6: 8500 | H6: 14000 | I6: =F6*H6 -> 518000
A7: 4 | B7: Thanadol Lerdsakcharoenkul | C7: IT Security Engineer | D7: Security | E7: Officer | F7: 3 | G7: 8500 | I7: =SUM(I4:I6) -> 1193000
F12: =SUM(F4:F7) -> 100 | G12: =(G4*F4)+(G5*F5)+(G6*F6)+(G7*F7) -> 1180000
A13: Other Information | C13: Total Amount (Baht)
A14: 1 | B14: Hardware | C14: -
A15: 2 | B15: Software | C15: -
A16: 3 | B16: License | C16: -
A17: 4 | B17: Allowance | C17: -
A18: 5 | B18: ค่าดำเนินโครงการโดยที่ปรึกษาภายนอก | C18: -
A19: 6 | B19: DevOps Service
A21: หมายเหตุ ถ้ามีประเภทค่าใช้จ่ายอื่นๆ เพิ่มเติมใน Project เพิ่ม Row ได้
I23: 1000000
I24: 1190000
H25: Total | I25: 2190000

Sheet Total
B1: โครงการ ENH-PTTEP-iCMS 2026 Enhancement | C1: ระยะเวลาโครงการ 172 วัน
B3: Digital Rev (BD Phase) | C3: =DGT_Manday!I44 -> 21000
B4: Digital Rev (Development Phase) | C4: =DGT_Manday!I45 -> 1159000
B5: ค่าเบี้ยเลี้ยง/ค่าเดินทาง | C5: =E15+E22 -> 0
B6: Vendor Cost + 10 %
B7: Total | C7: =SUM(C3:C6) -> 1180000
B10: ค่าเดินทาง | C10: จำนวนครั้ง | D10: ครั้งละ | E10: รวมค่าเดินทาง
B11: N/A
D15: Total
B17: ค่าเบี้ยเลี้ยง | C17: จำนวนครั้ง | D17: ครั้งละ | E17: รวมค่าเบี้ยเลี้ยง
B18: N/A
D22: Total
B25: งวดการชำระเงิน PTT >> PTT Digital | C25: % | D25: จำนวนเงิน
B26: งวดที่ 1 : Requirement & Design | C26: 0.3 | D26: =C9*C26 -> 0 | G26: Cost Performance
B27: งวดที่ 2 : Golive | C27: 0.7 | D27: =C9*C27 -> 0
C29: =SUM(C26:C28) -> 1 | D29: =SUM(D26:D28) -> 0
G30: Digital Cost + Vendor | H30: =#REF!+Total!E15+Total!E22+DGT_Manday!H49 -> #REF!
G31: Add Overhead | H31: =H30*1.14 -> #REF!
B32: งวดการชำระเงิน PTT Digital >> Vendor | C32: % | D32: จำนวนเงิน | G32: Margin | H32: =C7-H31 -> #REF!
G33: % Margin | H33: =H32/H31 -> #REF!

Sheet DGT_Manday
A1: =Total!B1 -> โครงการ ENH-PTTEP-iCMS 2026 Enhancement
A2: =Total!C1 -> ระยะเวลาโครงการ 172 วัน | D2: Sr1 | E2: Sr1 | F2: Sr1 | G2: Sr1 | H2: Of1
A3: Phase | B3: Details | C3: Deliverables | D3: PM | E3: BA/Tester | F3: Sr. Developer | G3: Developer | H3: Security
D4: Wannaporn Jaemklam | E4: Wannaporn Jaemklam | F4: Wissanu Tangtrongkijwong | G4: Niti Wisatchanam | H4: Thanadol Lerdsakcharoenkul
A5: Business Development | B5: Gather Initial Requirements | C5: Proposal, TOR | E5: 1
B6: Create Proposal | D6: 0.5
A7: Project Management | B7: Kick-Off Meeting | D7: 0.25
B8: Create Project Plan, Other Plans and Integrate to Project Plan | D8: 0.5
B9: Project Monitoring (23*0.125) | D9: 3
B10: Bi-Weekly Update Progress (10*0.25) | D10: 3
A11: Requirement Development | B11: Get Requirement | E11: 2 | F11: 1
B12: Confirm Requirement | E12: 0.5
A13: Design | B13: Review Requirment & Design Spec | C13: Sign-Off Requirement & Design Specification | E13: 2
B14: Confirm Requirment & Design Spec | E14: 0.5
B15: Sign off Requirement & Design Specification | D15: 0.25
A16: Software Development | B16: Prepare and setup Dev, SIT, UAT Environment | E16: 0.5
B17: Development + Unit Test
B18: PPS_001 ดำเนินการปรับปรุงการแสดงผลข้อมูลในระบบ โดยเปลี่ยนการแสดงผลจาก Major เป็น Discipline-Based JCP และจาก Minor เป็น Job-Based JCP ในทุกส่วนที่มีการแสดงข้อมูล - 16 Menu สำหรับพนักงาน - 2 Menu สำหรับ Admin - 13 Report - 1 Dashboard | F18: 2.5 | G18: 4
B19: PPS_002 ดำเนินการปรับปรุงการจัดเก็บข้อมูล Model สำหรับ Common Competency | F19: 1
B20: PPS_003 ดำเนินการปรับปรุงการกำหนดค่า Mandatory และ Target Score สำหรับ Common Competency | F20: 1
B21: PPS_004 ดำเนินการปรับปรุงระบบให้รองรับการ Mapping ข้อมูล Evidence ของ Soft Skill ไปยัง Common Competency | F21: 2
B22: PPS_005 ดำเนินการปรับปรุงการแสดงผลบนหน้าจอ, Report และ Dashboard ภายในระบบ เพื่อรองรับการประเมินด้วย Model Common Competency | F22: 18.5 | G22: 28
B23: Menu ที่ต้องปรับปรุงมีดังนี้ - Self Assessment – Staff (2.5,3) - Salf Assessment – Summary (0, 0.5) - ICDP – Staff (1,2) - Add Unplanned ICDP (1,0) - Self Assessment – Export Excel (0.5,2) - Salf Assessment - Export ICDP (0.5,2) - RP015 Technical & Soft Skill Calibration Report (For Employee) (0.5,2) - RP008 Individual Proficiency Report (GG & PE Only) (1,0.5) - Review Assessment & Plan ICDP (0.5,1) - Review Assessment & Plan ICDP – Multiple Review (1,5) - Track Your Team Progress ICDP (0.5,1)
B24: Menu สำหรับ Admin ที่ต้องปรับปรุงมีดังนี้ - Import JFM Calibration (1,0) - Import Panel Assessment (1,0)
B25: Report สำหรับ Admin ที่ต้องปรับปรุงมีดังนี้ - RP012 Promotion Candidate Shortlist Report (1,0.5) - RP012 Promotion Candidate Shortlist Report (New) (1,0.5) - RP015 Technical & Soft Skill Calibration Report (For Admin) (0.5,3) - RP015 Technical & Soft Skill Calibration Report (SA) (1,3) - RP016 Competency Inventory Report (1,0.5) - RP018 ICDP Report (1,1)
B26: Dashboard ที่ต้องปรับปรุงมีดังนี้ - Top 10 of Gap Ranking Competency (2,0.5)
B27: PPS_006 ดำเนินการปรับปรุงสิทธิ์สำหรับ Technical Reviewer โดยกำหนดให้ไม่สามารถดำเนินการประเมินเอกสารในส่วนของ Common Competency ของพนักงานได้ | F27: 0.5 | G27: 1
B28: PPS_007 ดำเนินการปรับปรุงสิทธิ์สำหรับ Technical Reviewer โดยกำหนดให้ไม่สามารถวางแผน ICDP ให้กับพนักงานได้ ทั้งในส่วนของ Common Competency และ Technical Competency | F28: 0.5 | G28: 1
B29: PPS_008 ดำเนินการปรับปรุงคู่มือการใช้งาน ให้สอดคล้องกับรูปแบบการประเมินปัจจุบัน | E29: 3
B30: Testing
B31: Create Test Scenario & Test Script | E31: 3
B32: System Integration Test (SIT) | E32: 5 | F32: 1 | G32: 1
B33: User Acceptance Test (UAT) | D33: 0.25 | E33: 2.5 | F33: 2 | G33: 2
B34: Perform Security Test | H34: 3
A35: Final Preparation | B35: Develop Deployment Plan & QA Process | C35: Sign-Off GO Live | E35: 1
B36: Prepare and setup Production Environment | E36: 0.5
B37: Production Deployment (Go-Live) | E37: 0.5
B38: Go-Live Sign-Off | D38: 0.25
A39: Project Closure | B39: Support After Go-Live
A40: Total | D40: =SUM(D5:D39) -> 8 | E40: =SUM(E5:E39) -> 22 | F40: =SUM(F5:F39) -> 30 | G40: =SUM(G5:G39) -> 37 | H40: =SUM(H5:H39) -> 3 | I40: =SUM(D40:H40) -> 100
...

Sheet Timeline
A1: =Total!B1 -> โครงการ ENH-PTTEP-iCMS 2026 Enhancement
A2: =DGT_Manday!A2 -> ระยะเวลาโครงการ 172 วัน
A5: ENH-PTTEP-iCMS 2026 Enhancement
A6: Project Activity | B6: Role | C6: M1 | K6: M2 | S6: M3 | AA6: M4 | AI6: M5 | AQ6: M6 | AY6: M7
C7: W1 | E7: W2 | G7: W3 | I7: W4 | K7: W1 | M7: W2 | O7: W3 | Q7: W4 | S7: W1 | U7: W2 | W7: W3 | Y7: W4 | AA7: W1 | AC7: W2 | AE7: W3 | AG7: W4 | AI7: W1 | AK7: W2 | AM7: W3 | AO7: W4 | AQ7: W1 | AS7: W2 | AU7: W3 | AW7: W4 | AY7: W1 | BA7: W2 | BC7: W3 | BE7: W4
A8: Project Preparation
A9: - Kick Off Meeting | B9: PM, BA, Dev, User
A10: Requirement + Design
A11: - Prepare/Review Requirement & Design | B11: PM, BA, Dev, User
A12: - Confirm Requirement & Design | B12: PM, BA, Dev, User
A13: - Requirement & Design Sign Off | B13: PM, BA, Dev, User
A14: Development
A15: - Development | B15: Dev
A16: Testing
A17: - Prepare Test Script | B17: BA, Tester
A18: - Integration Test and Unit Test | B18: BA, Tester
A19: - User Acceptance Testing | B19: PM, BA, Tester, User
A20: System Preparation
A21: - Update User Manual | B21: Security
A22: - Security Scan/ Source Code Review | B22: Security
A23: - Production Installation & Setting | B23: PM, Infra. Team
A24: - Go-Live / Go-Live Sign Off | B24: PM, User
A25: Support After Go-live
A26: - Support After Go-live | B26: BA, PM, Dev, User

Sheet Timeline 2 POT
A1: =Total!B1 -> โครงการ ENH-PTTEP-iCMS 2026 Enhancement
A2: =DGT_Manday!A2 -> ระยะเวลาโครงการ 172 วัน
A4: ENH-PTTEP-iCMS for Job Family Restructuring
A5: Project Activity | B5: Role | C5: M1 (Mar) | K5: M2 (Apr) | S5: M3 (May) | AA5: M4 (Jun) | AI5: M5 (Jul) | AQ5: M6 (Aug) | AY5: M7 (Sep) | BG5: M8 (Oct) | BO5: M9 (Nov)
C6: W1 | E6: W2 | G6: W3 | I6: W4 | K6: W1 | M6: W2 | O6: W3 | Q6: W4 | S6: W1 | U6: W2 | W6: W3 | Y6: W4 | AA6: W1 | AC6: W2 | AE6: W3 | AG6: W4 | AI6: W1 | AK6: W2 | AM6: W3 | AO6: W4 | AQ6: W1 | AS6: W2 | AU6: W3 | AW6: W4 | AY6: W1 | BA6: W2 | BC6: W3 | BE6: W4 | BG6: W1 | BI6: W2 | BK6: W3 | BM6: W4 | BO6: W1 | BQ6: W2 | BS6: W3 | BU6: W4
A7: Project Preparation
A8: - Kick Off Meeting | B8: PM, BA, Dev, User
A9: Requirement + Design
A10: - Prepare/Review Requirement & Design | B10: PM, BA, Dev, User
A11: - Confirm Requirement & Design | B11: PM, BA, Dev, User
A12: - Requirement & Design Sign Off | B12: PM, BA, Dev, User
A13: Development
A14: - Development | B14: Dev
A15: Testing
A16: - Prepare Test Script | B16: BA, Tester
A17: - Integration Test and Unit Test | B17: BA, Tester
A18: - User Acceptance Testing | B18: PM, BA, Tester, User
A19: System Preparation
A20: - Security Scan/ Source Code Review | B20: Security
A21: - Production Installation & Setting | B21: PM, Infra. Team
A22: - Go-Live / Go-Live Sign Off | B22: PM, User
A23: Support After Go-live
A24: - Support After Go-live | B24: BA, PM, Dev, User
A25: ENH-PTTEP-iCMS 2026 Enhancement
A26: Project Preparation
A27: - Kick Off Meeting | B27: PM, BA, Dev, User
A28: Requirement + Design
A29: - Prepare/Review Requirement & Design | B29: PM, BA, Dev, User
A30: - Confirm Requirement & Design | B30: PM, BA, Dev, User
A31: - Requirement & Design Sign Off | B31: PM, BA, Dev, User
A32: Development
A33: - Development | B33: Dev
A34: Testing
A35: - Prepare Test Script | B35: BA, Tester
A36: - Integration Test and Unit Test | B36: BA, Tester
A37: - User Acceptance Testing | B37: PM, BA, Tester, User
A38: System Preparation
A39: - Update User Manual | B39: Security
A40: - Security Scan/ Source Code Review | B40: Security
A41: - Production Installation & Setting | B41: PM, Infra. Team
...
