Workbook
Name _Hlk175834902: 'Cost Brakedown Templete'!#REF!
Name _Hlk44493142: 'Project team'!$A$1
Name PriceRole: 'Cost Brakedown Templete'!#REF!
Name PriceRole: #REF!
Name Role: 'Cost Brakedown Templete'!#REF!
Name Role: #REF!

Sheet Grand Total
B2: ส่วนที่ 1 | C2: ค่าดำเนินโครงการ PTT Digital
G3: =ICT_Manday!D62 -> Cost (BD Phase) | H3: =ICT_Manday!O62 -> 185500
G4: =ICT_Manday!D63 -> Cost (Development Phase) | H4: =ICT_Manday!O63 -> 3938000
G5: Total | H5: =SUM(H3:H4) -> 4123500
B9: ส่วนที่ 2 | C9: ค่าดำเนินโครงการโดยที่ปรึกษาภายนอก
G10: Vendor | H10: ='Vendor Cost'!E16 -> 7100000
G11: Vendor +10% | H11: =H10*110% -> 7810000
G12: Total | H12: =H11 -> 7810000
B15: ส่วนที่ 3 | C15: ค่าใช้จ่ายอื่นๆ
D16: PM | E16: BA | F16: Infra | G16: ค่าใช้จ่ายอื่นๆ
B17: เบี้ยเลี้ยง | C17: 600 | G17: เบี้ยเลี้ยง | H17: =(C17*D17)+(C17*E17)+(C17*F17) -> 0
B18: ที่พัก | C18: 2500 | G18: ที่พัก | H18: =(C18*D18)+(C18*E18)+(C18*F18) -> 0
B19: ค่าเดินทาง | C19: 2500 | G19: ค่าเดินทาง | H19: =(C19*D19)+(C19*E19)+(C19*F19) -> 0
G20: Total | H20: =SUM(H17:H19) -> 0
G24: Grand Total | H24: =SUM(H5+H12+H20) -> 11933500 | J24: 11938700
J25: =H24-J24 -> -5200
G26: Budget

Sheet ICT_Manday
A1: โครงการ PJR-PTT-eMOC GSP
A2: (ระยะเวลาโครงการ 18 เดือน)
A3: Phase | B3: Details | C3: Standard | D3: Deliverables | E3: PM | F3: BA | G3: Tester | H3: SA | I3: WSO2 | J3: WSO2 | K3: Azure AD, B2C Developer zchayapon.m | L3: Infra Server IFM/O zpachara.s | M3: Infra Server DevOps zpatchara.m | N3: Security chanvut.c | O3: Vendor
E4: Wilaiwan | F4: Sudarat | G4: Sudarat | H4: Sudarat | I4: Panuwat | J4: Tawit | M4: IFM/O
A5: Business Development | B5: Gather Initial Requirements | D5: Proposal, TOR | E5: 5 | F5: =3+2 -> 5
B6: Vendor Selection | E6: 2
B7: Impact analyst | E7: 2 | F7: =1+1 -> 2
A8: Project Planning | B8: Kick-Off Meeting | C8: x | E8: 1 | F8: 1
B9: Create Project Plan, Other Plans and Integrate to Project Plan | C9: x | E9: 1
B10: WBS & Risk Management | C10: x | E10: 0.5
B11: Control & Monitoring | E11: =18*3 -> 54
B12: Prepare and setup Development Environment | C12: x | E12: 1 | H12: 1 | K12: 1 | L12: 4 | M12: 5
A13: Requirement Development | B13: Gather Requirement Details | E13: 12 | F13: =5+2+5 -> 12
B14: Create Requirement Specification | E14: 2 | F14: =1+1 -> 2
B15: Peer Review Requirement Specification | E15: 2 | F15: =1+1 -> 2
B16: Confirm Requirement Specification with Customer | E16: 3 | F16: =1+1+1 -> 3
B17: Sign off Requirement Specification | C17: x | E17: 0.5
B18: Create Baseline for Design(CM) | C18: x | E18: 0.5
A19: Design | B19: Create Design Specification | E19: 2 | F19: =1+1 -> 2
B20: Peer Review Design Specification | D20: Sign-Off Requirement & Design Specification | E20: 2 | F20: =1+1 -> 2
B21: Clarify Design with Customer | E21: 2 | F21: =1+1 -> 2
B22: Sign off Design Specification | C22: x | E22: 0.5
B23: Create Business Scenario Test case | E23: 3 | G23: =2+1+2 -> 5
B24: Peer Review Technical Specification | E24: 2 | F24: =1+1 -> 2
A25: Development | B25: Coding & Config | G25: 3 | I25: =8+2 -> 10 | J25: 1
B26: Connect WSO2
B27: Data migration
B28: Extraction | E28: 3 | H28: =3+3+3 -> 9
B29: Transform | E29: 3 | H29: =3+3+3 -> 9
B30: Preload sign-off | E30: 3
B31: Loading | E31: 3 | H31: =3+3+3 -> 9
B32: Postload sign-off | E32: 3
B33: Functional Unit Test | E33: 12 | G33: =4+3+5 -> 12
A34: Testing | B34: System Integration Test | E34: 12 | G34: =4+3+5 -> 12
B35: User Acceptance Test | E35: 16 | G35: =5+5+6 -> 16
B36: Perform Security Test & Load Test & Source code GIT hub | E36: 2 | G36: =1+1 -> 2 | N36: 3
B37: Source Code Scan (Coverity and Black Duck) | D37: x | H37: 1
B38: Container Image Scan (Trivy) | D38: x | H38: 1
B39: Security Scan (OWASP ZAP) | D39: x | H39: 1
B40: Quality Scan (SonarQube) | D40: x | H40: 1
...

Sheet Man-day-SAP Team
A1: No. | B1: SAP Function Module | C1: Description | D1: Comment | E1: Comment (Suthat) | F1: ABAP | G1: ABAP (New Estimate) | H1: SAP PI (New Estimate) | I1: WSO2 (New Estimate) | J1: SAP PM (New Estimate) | K1: BASIS (New Estimate) | L1: SAP Master (New Estimate) | M1: CR SAP PI | N1: CR WSO2
A2: 1 | B2: Modify ZPIPMI032 | C2: PM Notification | D2: การสร้าง Notification ผ่านทาง EIR การ Release Notification ผ่านทาง EIR | E2: 1. add new fields from ZPMPME050 2. Change user status and add long text in Notification | F2: 1 | G2: 5 | H2: =2+M2 -> 2.5 | I2: =1+N2 -> 1 | J2: 5 | K2: 2 | M2: 0.5
A3: 2 | B3: Modify ZPIPMI033 | C3: Work Order | D3: การสร้าง/แก้ไข/Release/Close Order ผ่านทาง EIR การ Close Notification ผ่านทาง EIR | E3: 1. add new fields from ZPMPME070 2. Change user status and add long text in Notification | F3: 1 | G3: 5 | H3: =2+M3 -> 2.5 | I3: =1+N3 -> 1 | J3: 5 | M3: 0.5
A4: 3 | B4: ZPIPMI034 | C4: Attach URL | D4: การแนบ URL Link ใน Notification ผ่านทาง EIR การแนบ URL Link ใน Order ผ่านทาง EIR | E4: Reuse ได้ | F4: 1 | G4: 1 | H4: =2+M4 -> 2 | I4: =1+N4 -> 1 | J4: 2
A5: 4 | B5: n/a | C5: SAP Master | D5: SAP Master - Create user + Grant Read only table PM_FL, PM_EQ, PM_NOTI, PM_ORDER, PM_ORDER_OPERATION, PM_LONGTEXT, PM_CLASS, PM_LOCATION (for ECD, EC2, ECP) | E5: ขอ view ที่ EDP Data lake ผบ ติดต่อคุณยิ้ม ธนาภรณ์ น้อยรักษา (560304) THANAPORN.KL@PTTPLC.COM PTT Digital EDP คุณ สุรฤทธิ์ Surarit Chaisuntharanon surarit.c@pttdigital.com | H5: =0+M5 -> 0 | I5: =0+N5 -> 0 | J5: 1 | L5: 2
A6: 5 | B6: ZPIPMI045 | C6: PM Time confirmation | D6: การทำ Time confirmation ผ่านทาง EIR (Reuse Pyramid) | E6: สามารถ Reuse ได้ สอบถามหน่วยงาน ผบ ติดต่อคุณยิ้ม ธนาภรณ์ น้อยรักษา (560304) THANAPORN.KL@PTTPLC.COM PTT Digital EDP คุณ สุรฤทธิ์ Surarit Chaisuntharanon surarit.c@pttdigital.com | F6: 1 | G6: 1 | H6: =2+M6 -> 2 | I6: =1+N6 -> 1 | J6: 2
A7: 6 | B7: New ZPIPMIxxx | C7: Get RAM Matrix | D7: Get Constant table ZBC_ROLLOUT_CONS REPID = ZPMPME050 and ZPMPME070 | E7: ส่ง RAM Matrix จาก SAP ให้ EIR เพื่อที่จะได้มี RAM Matrix ที่เดียว หากมีการเปลี่ยนแปลงก็จะไม่ต้องแก้ไข 2 ที่ | G7: 3 | H7: =0+M7 -> 3 | I7: =0+N7 -> 1 | J7: 1 | M7: 3 | N7: 1 | P7: 1. RFC Function 2. ต้องการเอา data จาก ZBC_ROLLOUT_CONS ขึ้น EIR | R7: Mode:- 1=GET CONSTANT 2=READ OBJECT 3.=UPDATE OBJECT IT_OBJECT_ID
A8: 7 | B8: New ZPIPMIyyy | C8: Get/Update Attachement link | D8: call FM SO_OBJECT_READ SO_OBJECT_UPDATE | E8: Call FM SO_OBJECT_READ SO_OBJECT_UPDATE | G8: 4 | H8: 3 | I8: 1 | J8: 2 | M8: 3 | N8: 1 | P8: 3. Mode Read Object 4. Mode Update Object | R8: Mode:- 1=GET CONSTANT 2=READ OBJECT 3.=UPDATE OBJECT IT_OBJECT_ID
A9: 8 | B9: Modify ZPMPME050 | C9: RAM Notification | D9: - Verify data before release (created from ZPIPMI032) - Support testing ZPIPMI032, ZPIPMI033 | G9: 2 | J9: 2
A10: 9 | B10: Modify ZPMPME070 | C10: RAM Order | D10: - Fix case Display mode IW23 --> IW33 - Support testing ZPIPMI032, ZPIPMI033 | G10: 2 | J10: 2
F11: =SUM(F2:F6) -> 4 | G11: =SUM(G2:G10) -> 23 | H11: =SUM(H2:H10) -> 15 | I11: =SUM(I2:I10) -> 6 | J11: =SUM(J2:J10) -> 22 | K11: =SUM(K2) -> 2 | L11: =SUM(L2:L10) -> 2 | M11: =SUM(M2:M7) -> 4 | N11: =SUM(N2:N7) -> 1
C14: SAP PM Sr. | D14: Suthat Lerdarunwatthana
C15: ABAP | D15: Duangjai Channum | E15: รวม | G15: =G11+H11+I11+J11+K11+L11 -> 70
C16: PI Jr. | D16: Supharoek Wutthichaipradit
C17: WSO2 Jr. | D17: Panuwat Paitakaew
C18: WSO2 Sr. | D18: Tawit Choedkiatsakul
C19: Basis Sr. | D19: Kiattisak Banlengchit
C20: SAP Master Sr. | D20: Chonticha Makkata

Sheet Vendor Cost
C2: โครงการ PJR-PTT-eMOC GSP
C3: Vendor :Pheonix Modern, The Iceland
C5: Order | D5: Description | E5: Cost
C6: 1 | D6: ค่า PJR-PTT-eMOC GSP รวม GSP, Khanom, EPT | E6: 7100000
F7: =E7*110% -> 0
F8: =E8*110% -> 0
D14: Total | E14: =SUM(E6:E13) -> 7100000
D15: Discount
D16: Grand Total | E16: =E14-E15 -> 7100000
D17: ราคานี้ยังไม่รวม Vat 7%
D22: 1. ชำระงวดแรก | E22: 0.2 | F22: =$E$16*E22 -> 1420000 | G22: ตามมูลค่าของโครงการเมื่อส่งมอบเอกสาร Sign-Off Requirement & Design
D23: 2. ชำระงวดที่สอง | E23: 0.2 | F23: =$E$16*E23 -> 1420000 | G23: ตามมูลค่าของโครงการเมื่อส่งมอบเอกสาร Sign-Off Go live
D24: 3. ชำระงวดที่สาม | E24: 0.3 | F24: =$E$16*E24 -> 2130000
D25: 4. ชำระงวดที่สี่ | E25: 0.3 | F25: =$E$16*E25 -> 2130000

Sheet Project Timeline_Revise
A1: Phase | C1: Task | D1: M1 | H1: M2 | L1: M3 | P1: M4 | T1: M5 | X1: M6 | AB1: M7 | AF1: M8 | AJ1: M9 | AN1: M10 | AR1: M11 | AV1: M12 | AZ1: M13 | BD1: M14 | BH1: M15 | BL1: M16 | BP1: M17 | BT1: M18
D2: W1 | E2: W2 | F2: W3 | G2: W4 | H2: W1 | I2: W2 | J2: W3 | K2: W4 | L2: W1 | M2: W2 | N2: W3 | O2: W4 | P2: W1 | Q2: W2 | R2: W3 | S2: W4 | T2: W1 | U2: W2 | V2: W3 | W2: W4 | X2: W1 | Y2: W2 | Z2: W3 | AA2: W4 | AB2: W1 | AC2: W2 | AD2: W3 | AE2: W4 | AF2: W1 | AG2: W2 | AH2: W3 | AI2: W4 | AJ2: W1 | AK2: W2 | AL2: W3 | AM2: W4 | AN2: W1 | AO2: W2 | AP2: W3 | AQ2: W4 | AR2: W1 | AS2: W2 | AT2: W3 | AU2: W4 | AV2: W1 | AW2: W2 | AX2: W3 | AY2: W4 | AZ2: W1 | BA2: W2 | BB2: W3 | BC2: W4 | BD2: W1 | BE2: W2 | BF2: W3 | BG2: W4 | BH2: W1 | BI2: W2 | BJ2: W3 | BK2: W4 | BL2: W1 | BM2: W2 | BN2: W3 | BO2: W4 | BP2: W1 | BQ2: W2 | BR2: W3 | BS2: W4 | BT2: W1 | BU2: W2 | BV2: W3 | BW2: W4
A3: Phase : GSP RYG&KHM - Project Preparation & Software Requirement
A4: Kick-off Project | B4: 1 | C4: Kick off Project
A5: Gather Requirement | B5: 2 | C5: รวบรวม Requirement ส่วนงาน GSP RYG&KHM
B6: 3 | C6: Sign off Requirement Specification ส่วนงาน GSP RYG&KHM
A7: Phase : GSP RYG&KHM - Software Design
A8: Design System | B8: 5 | C8: TO-BE Software Design ส่วนงาน GSP RYG&KHM
B9: 6 | C9: Present Software Design ส่วนงาน GSP RYG&KHM
A10: Design Infrastructure | B10: 4 | C10: จัดเตรียม Infrastructure
B11: 7 | C11: Sign-off Design Specification ส่วนงาน GSP RYG&KHM
A12: Sign-off #1 | C12: Milestone#1 RYG,KNM Requirement & Design Sign-off
A13: Phase : EPT - Project Preparation (Total 10%)
A14: Gather Requirement | B14: 8 | C14: รวบรวม Requirement ส่วนงาน EPT
B15: 9 | C15: Sign off Requirement Specification ส่วนงาน EPT
A16: Phase : EPT - Software Design
A17: Design System | B17: 10 | C17: TO-BE Software Design ส่วนงาน EPT
B18: 11 | C18: Present Software Design ส่วนงาน EPT
B19: 12 | C19: Sign-off Design Specification ส่วนงาน EPT
A20: Sign-off #2 | C20: Milestone#2 EPT Requirement & Design Sign-off
A21: Phase : GSP RYG&KHM - Development & Testing
A22: Prepare Technical Document & Build Application | B22: 13 | C22: Configuration
B23: 14 | C23: Coding / Install to Test System ส่วนงาน GSP RYG&KHM
B24: 15 | C24: Unit Test ส่วนงาน GSP RYG&KHM
A25: Integration Test (SIT) | B25: 16 | C25: Interface Test ส่วนงาน GSP RYG&KHM
B26: 17 | C26: System Integration Test ส่วนงาน GSP RYG&KHM
A27: User Acceptance Test (UAT) | B27: 18 | C27: User Acceptance Test ส่วนงาน GSP RYG&KHM
B28: 19 | C28: Sign-off User Acceptance Test ส่วนงาน GSP RYG&KHM
A29: Sign-off #3 | C29: Milestone#3 RYG,KNM User Acceptance Test Sign-off
A30: Phase : GSP RYG&KHM - Deployment & Support
A31: Performance & Security Test | B31: 20 | C31: Peformance & Security Test
C32: 20.1 Performance Test (Load Test)
C33: 20.2 Security Test
A34: Training & Prepare Production Environment | B34: 21 | C34: Deployment ส่วนงาน GSP RYG&KHM
B35: 22 | C35: Training ส่วนงาน GSP RYG
B36: 23 | C36: Training ส่วนงาน GSP KHM
B37: 24 | C37: User & Admin Manual ส่วนงาน GSP RYG&KHM
B38: 25 | C38: Technical Manual ส่วนงาน GSP RYG&KHM
B39: 26 | C39: Migration Data ส่วนงาน GSP RYG&KHM
B40: 27 | C40: Go-Live ส่วนงาน GSP RYG&KHM
...

Sheet Project Timeline
A1: Phase | C1: Task | D1: M1 | H1: M2 | L1: M3 | P1: M4 | T1: M5 | X1: M6 | AB1: M7 | AF1: M8 | AJ1: M9 | AN1: M10 | AR1: M11 | AV1: M12 | AZ1: M13 | BD1: M14 | BH1: M15 | BL1: M16 | BP1: M17 | BT1: M18 | BX1: M19 | CB1: M20 | CF1: M21 | CJ1: M22
D2: W1 | E2: W2 | F2: W3 | G2: W4 | H2: W1 | I2: W2 | J2: W3 | K2: W4 | L2: W1 | M2: W2 | N2: W3 | O2: W4 | P2: W1 | Q2: W2 | R2: W3 | S2: W4 | T2: W1 | U2: W2 | V2: W3 | W2: W4 | X2: W1 | Y2: W2 | Z2: W3 | AA2: W4 | AB2: W1 | AC2: W2 | AD2: W3 | AE2: W4 | AF2: W1 | AG2: W2 | AH2: W3 | AI2: W4 | AJ2: W1 | AK2: W2 | AL2: W3 | AM2: W4 | AN2: W1 | AO2: W2 | AP2: W3 | AQ2: W4 | AR2: W1 | AS2: W2 | AT2: W3 | AU2: W4 | AV2: W1 | AW2: W2 | AX2: W3 | AY2: W4 | AZ2: W1 | BA2: W2 | BB2: W3 | BC2: W4 | BD2: W1 | BE2: W2 | BF2: W3 | BG2: W4 | BH2: W1 | BI2: W2 | BJ2: W3 | BK2: W4 | BL2: W1 | BM2: W2 | BN2: W3 | BO2: W4 | BP2: W1 | BQ2: W2 | BR2: W3 | BS2: W4 | BT2: W1 | BU2: W2 | BV2: W3 | BW2: W4 | BX2: W1 | BY2: W2 | BZ2: W3 | CA2: W4 | CB2: W1 | CC2: W2 | CD2: W3 | CE2: W4 | CF2: W1 | CG2: W2 | CH2: W3 | CI2: W4 | CJ2: W1 | CK2: W2 | CL2: W3 | CM2: W4
A3: Phase : GSP RYG&KHM - Project Preparation & Software Requirement
A4: Kick-off Project | B4: 1 | C4: Kick off Project
A5: Gather Requirement | B5: 2 | C5: รวบรวม Requirement ส่วนงาน GSP RYG&KHM
B6: 3 | C6: Sign off Requirement Specification ส่วนงาน GSP RYG&KHM
A7: Phase : GSP RYG&KHM - Software Design
A8: Design System | B8: 5 | C8: TO-BE Software Design ส่วนงาน GSP RYG&KHM
B9: 6 | C9: Present Software Design ส่วนงาน GSP RYG&KHM
A10: Design Infrastructure | B10: 4 | C10: จัดเตรียม Infrastructure
B11: 7 | C11: Sign-off Design Specification ส่วนงาน GSP RYG&KHM
A12: Sign-off #1 | C12: Milestone#1 RYG,KNM Requirement & Design Sign-off
A13: Phase : EPT - Project Preparation (Total 10%)
A14: Gather Requirement | B14: 8 | C14: รวบรวม Requirement ส่วนงาน EPT
B15: 9 | C15: Sign off Requirement Specification ส่วนงาน EPT
A16: Phase : EPT - Software Design
A17: Design System | B17: 10 | C17: TO-BE Software Design ส่วนงาน EPT
B18: 11 | C18: Present Software Design ส่วนงาน EPT
B19: 12 | C19: Sign-off Design Specification ส่วนงาน EPT
A20: Sign-off #2 | C20: Milestone#2 EPT Requirement & Design Sign-off
A21: Phase : GSP RYG&KHM - Development & Testing
A22: Prepare Technical Document & Build Application | B22: 13 | C22: Configuration
B23: 14 | C23: Coding / Install to Test System ส่วนงาน GSP RYG&KHM
B24: 15 | C24: Unit Test ส่วนงาน GSP RYG&KHM
A25: Integration Test (SIT) | B25: 16 | C25: Interface Test ส่วนงาน GSP RYG&KHM
B26: 17 | C26: System Integration Test ส่วนงาน GSP RYG&KHM
A27: User Acceptance Test (UAT) | B27: 18 | C27: User Acceptance Test ส่วนงาน GSP RYG&KHM
B28: 19 | C28: Sign-off User Acceptance Test ส่วนงาน GSP RYG&KHM
A29: Sign-off #3 | C29: Milestone#3 RYG,KNM User Acceptance Test Sign-off
A30: Phase : GSP RYG&KHM - Deployment & Support
A31: Performance & Security Test | B31: 20 | C31: Peformance & Security Test
C32: 20.1 Performance Test (Load Test)
C33: 20.2 Security Test
A34: Training & Prepare Production Environment | B34: 21 | C34: Deployment ส่วนงาน GSP RYG&KHM
B35: 22 | C35: Training ส่วนงาน GSP RYG
B36: 23 | C36: Training ส่วนงาน GSP KHM
B37: 24 | C37: User & Admin Manual ส่วนงาน GSP RYG&KHM
B38: 25 | C38: Technical Manual ส่วนงาน GSP RYG&KHM
B39: 26 | C39: Migration Data ส่วนงาน GSP RYG&KHM
B40: 27 | C40: Go-Live ส่วนงาน GSP RYG&KHM
...

Sheet Project team
A1: รายชื่อผู้ดำเนินงานหลักของโครงการและช่องทางการติดต่อ
A2: ลำดับ | B2: ชื่อ-นามสกุล | C2: ตำแหน่ง | D2: หน่วยงาน | E2: หมายเลขติดต่อ | F2: Email Address
D3: และบริษัท
A4: 1 | B4: คุณธีรสันต์ กูลมงคลรัตน์ | C4: Project Sponsor | D4: PTT | E4: 038-676-104 | F4: teerasan.k@pttplc.com
A5: 2 | B5: คุณภากร สุริยาภิวัฒน์ | C5: Project Sponsor | D5: PTT | E5: 952516253 | F5: pakorn.suriya@pttplc.com
A6: 3 | B6: คุณกลศ บุณยะวรรธนะ | C6: Project Advisor | D6: PTT | E6: 038-676-400 | F6: klot.b@pttplc.com
A7: 4 | B7: คุณวิภานันท์ รัตนบันดาล | C7: Key user | D7: PTT | E7: 038-676-415 | F7: wipanan.k@pttplc.com
A8: 5 | B8: คุณวรวิทย์ ย่องลั่น | C8: Key user | D8: PTT | E8: 075-304-441 | F8: worawit.y@pttplc.com
A9: 6 | B9: คุณจักรพันธ์ ศรียาภัย | C9: Key user | D9: PTT | E9: 075-304-441 | F9: jakaphan.s@pttplc.com
A10: 7 | B10: คุณภณินท์รัตน์ วิรานันท์ | C10: PMO & OCIO | D10: PTT | E10: 02-537-1350 | F10: phanintrat.w@pttplc.com
A11: 8 | B11: คุณมงคล น้อมรับพร | C11: PMO & OCIO | D11: PTT | E11: 091-566-5691 | F11: mongkol_n@pttplc.com
A12: 9 | B12: คุณจุไรรัตน์ ดำรงธรรม | C12: Project Sponsor | D12: PTT Digital | E12: 02-140-2028 | F12: jurairat.d@pttdigital.com
A13: 10 | B13: คุณศุภรดา อยู่เสดียง | C13: Project Advisor | D13: PTT Digital | E13: 092-289-6595 | F13: supharada.u@pttdigital.com
A14: 11 | B14: คุณวิไลวรรณ ภู่ถาวร | C14: Project Manager | D14: PTT Digital | E14: 086-068-3419 | F14: wilaiwan.p@pttdigital.com
A15: 12 | B15: คุณสุดารัตน์ ขจรรัตน์ | C15: Business Analyst, System Analyst, Tester | D15: PTT Digital | E15: 089-248-1305 | F15: zsudarat.k@pttdigital.com
A16: 13 | B16: คุณธวิทย์ เชิดเกียรติสกุล | C16: WSO2 API Developer | D16: PTT Digital | E16: 086-685-4586 | F16: tawit.c@pttdigital.com
A17: 14 | B17: คุณภานุวัฒน์ ไผ่ตาแก้ว | C17: WSO2 API Developer | D17: PTT Digital | E17: 095-650-1490 | F17: zpanuwat.pa@pttdigital.com
... A21: 18 | B21: คุณธนาดล เลิศศักดิ์เจริญกุล | C21: Security Engineer | D21: PTT Digital | E21: 084-702-2289 | F21: thanadol.l@pttdigital.com

Sheet Breakdown_Rev2
A1: รายละเอียดการชี้แจงการนำเสนองบประมาณบริการและโครงการต่อ GSP
A2: Service Name : | C2: ดำเนินการปรับปรุงระบบ MOC และ Override > 3 วัน ให้สอดคล้องตาม OEMS Framework
A3: Service Category : | C3: Application
A4: Service Type : | C4: Project&Enhance
A5: Budget Type : | C5: CAPEX
A6: PTT Digital Divison Owner : | C6: AOU/A
A7: ระบุชื่อส่วนงาน GSP ที่ใช้บริการ : | C7: วก.วบก.
A8: สถานะการใช้บริการ : | C8: Existing
A9: Total Budget Y25
A10: Total Budget Y26 | C10: 11938700
A11: Budget Trend (Y25 vs Y26) :
A12: จำนวนงบประมาณที่แตกต่างระหว่างปี 2025 และ 2026 :
A13: Remark : ข้อมูลเพิ่มเติมสนับสนุนเกี่ยวกับความสำคัญของโครงการเหตุผลที่ต้องทำ เพื่อทดแทน, พัฒนาหรือปิด Gap อะไร (ถ้ามี) | C13: ระบบ eMoC ของ GSP เป็นระบบที่ใช้ในการบริหารจัดการการดำเนินงานด้านการปรับปรุงหรือเปลี่ยนแปลงได้อย่างเหมาะสมและเป็นระบบที่มีการพิจารณาและให้ความเห็นชอบจากผู้ที่เกี่ยวข้อง ตามกรอบการดำเนินงานของ Operational Excellence Management System (OEMS) ซึ่งเป็นแนวทางที่บริษัทในกลุ่ม ปตท. ใช้เป็นกรอบในการจัดระบบบริหารจัดการภายในองค์กร โดย PTT Digital ได้เสนอเป็นการพัฒนาระบบงานใหม่ที่เป็น Modernize Application เพื่อ Replace ระบบงานเดิม โดยการประเมินได้รวมการพัฒนาของพื้นที่ โรงแยกก๊าซฯระยอง, โรงแยกก๊าซฯขนอม, คลังภาคตะวันออก โดย Key user ต้องการปรับปรุงดังนี้ 1. GSP มีแผนปรับปรุง MoC Procedure เพื่อให้เป็นไปตาม PTT Group’s Operational Excellence Management System (OEMS) และ Recommendation Practice (RP) ซึ่งเป็นแนวทางที่บริษัทในกลุ่ม ปตท. ใช้เป็นกรอบในการจัดระบบบริหารจัดการภายในองค์กร​ 2. Electronic Form สำหรับ การประเมินความเสี่ยง , ประเมินรายการใบอนุญาต, PSI Check List ​ 3. ระบบ Electronic Tracking Status สำหรับ Recommendation ระหว่างดำเนินการปรับปรุงเปลี่ยนแปลง​ 4. ระบบ Electronic PSSR Punch List Status ก่อนการส่งมอบ 5. ระบบ e-MOC มีปัญหาการใช้งานจากระบบเดิม เช่น การขอแก้ไขข้อมูล MOC, การแก้ไขผู้รับผิดชอบในแต่ละ Part, การบันทึกข้อมูลที่เปลี่ยนแปลงจากงาน Maintenance Change เป็นต้น ทำให้เกิดค่าใช้จ่ายในการ Request ขอดำเนินการขอแก้ไขข้อมูล 6. ​GSP ได้รับ GAP จากการตรวจประเมิน MOC 3rd MA ประจำปี 2566 โดย PTT Group ซึ่งมี Recommendation ทั้งหมด 37 หัวข้อ ด้วยเหตุผลดังกล่าวข้างต้น ทาง PTT Digital จึงได้เสนอเป็นการพัฒนาระบบงานใหม่ เพื่อ Replace ระบบงานเดิม เนื่องจากระบบงานเดิม ไม่สามารถที่จะปรับปรุงเพื่อแก้ไข ปัญหาจากระบบงานเดิมได้ทั้งหมด ด้วยเทคโนโลยีของระบบงานที่พัฒนามาตั้งแต่ปี 2015 ไม่สามารถที่จะ upgrade Tool ที่พัฒนาให้ใหม่ขึ้นกว่าเดิมได้ ทำให้การออกแบบและปรับปรุงระบบงานมีข้อจำกัดในการใช้งาน Tool
A14: การแจกแจง Task และที่มาการคิดค่าบริการ (Delivery)
A15: No. | B15: Task Type | D15: ประเภทค่าใช้จ่าย | E15: รายละเอียด Task ที่ต้องดำเนินการ | F15: Breakdown อัตราค่าบริการราย Task | G15: สถานะ Functions/Task (Required / Optional) | H15: กรณีเลือก Optional โปรดระบุ Impact หรือผลกระทบจากการตัด Function หรือ Service ดังกล่าว
A16: 1 | B16: Project Management | C16: Project Management | D16: ค่าแรง | E16: Project Manager | F16: 1918000 | G16: Required
A17: =A16+1 -> 2 | B17: Project Management | C17: Requirement Gathering | D17: ค่าแรง | E17: Business Analyst | F17: 467500 | G17: Required
A18: =A17+1 -> 3 | B18: Business Requirement | D18: ค่าแรง | E18: 1. รองรับการทำงานของ Work flow MOC – Plant Change – Permanent (Impact PSI) | F18: 596200 | G18: Required
A19: =A18+1 -> 4 | B19: Business Requirement | D19: ค่าแรง | E19: 2. รองรับการทำงานของ Work flow MOC – Plant Change – Temporary(Impact PSI) | F19: 596200 | G19: Required
A20: =A19+1 -> 5 | B20: Business Requirement | D20: ค่าแรง | E20: 3. รองรับการทำงานของ Work flow MOC – Plant Change – Permanent (No Impact PSI) | F20: 486200 | G20: Required
A21: =A20+1 -> 6 | B21: Business Requirement | D21: ค่าแรง | E21: 4. รองรับการทำงานของ Work flow MOC – Plant Change – Temporary(No Impact PSI) | F21: 486200 | G21: Required
A22: =A21+1 -> 7 | B22: Business Requirement | D22: ค่าแรง | E22: 5. รองรับการทำงานของ Work flow Overriding มากกว่า 3 วัน | F22: 268950 | G22: Required
A23: =A22+1 -> 8 | B23: Business Requirement | D23: ค่าแรง | E23: 6. รองรับการทำงานของ Work flow Overriding น้อยกว่า 3 วัน | F23: 365200 | G23: Required
A24: =A23+1 -> 9 | B24: Business Requirement | D24: ค่าแรง | E24: 7. รองรับการทำงานของ Work flow Emergency Change | F24: 262350 | G24: Required
A25: =A24+1 -> 10 | B25: Business Requirement | D25: ค่าแรง | E25: สามารถกรอกแบบฟอร์ม Online ได้ ดังนี้ 1. รองรับแบบฟอร์ม Preliminary Safety Assesment & PHA Review 2. รองรับแบบฟอร์ม PSI Master List 3. รองรับแบบฟอร์ม Override Risk Assessment 4. รองรับแบบฟอร์ม Government License Verification Checklist 5. รองรับแบบฟอร์ม SHE Assessment Check List Form 6. รองรับการคำนวณ Risk Ranking ตาม Risk Matrix ได้ | F25: 289300 | G25: Required
A26: =A25+1 -> 11 | B26: Business Requirement | D26: ค่าแรง | E26: Administrator สามารถปรับแก้ไข Workflow ได้ 1. สามารถเพิ่มขั้นตอนใน Workflow โดยขั้นตอนที่เพิ่มเป็นไปตามรายการ Workflow Item Template 2. สามารถระบุตัวบุคคลที่ต้องการให้ดำเนินการขั้นตอนใดใน Workflow ได้ โดยระบบรองรับ Role ที่มีการกำหนดไว้ในระบบ 3. รองรับการกำหนดขั้นตอนใน Workflow เป็นแบบ Sequential และ Parallel ได้ 4. สามารถแก้ไขและยกเลิกขั้นตอนใน Workflow ได้ 5. สามารถปรับแก้ไขข้อมูลที่เป็นตัวเลือกบนแบบฟอร์ม MOC ได้ เช่น รายการข้อมูลใน Drop Down List หรือใน Check box / Choice เป็นต้น (ไม่สามารถปรับแบบฟอร์มเช่นการเพิ่ม/ลด field บนแบบฟอร์มได้) เช่น Reason for Change, Document Check List เป็นต้น | F26: 541750 | G26: Required
A27: =A26+1 -> 12 | B27: Business Requirement | D27: ค่าแรง | E27: การ Interface ระบบงานที่เกี่ยวข้องจำนวน 6 ระบบงาน ได้แก่ 1. รองรับการเชื่อมต่อกับระบบ MPI Online เพื่อรองรับการส่งข้อมูลมาสร้าง MOC จากระบบ MPI Online 2. รองรับการ Interface กับระบบ PTT-GSP Daily report เพื่อดึงข้อมูลพนักงานที่สังกัด Plant GSP1,GSP2,GSP3 และพนักงานที่เป็นตำแหน่งหัวหน้าพนักงาน และส่งข้อมูลงาน Override ทั้งมากกว่าและน้อยกว่า 3 วัน ให้กับ PTT-GSP Daily report ผ่าน API WSO2 3. รองรับการเชื่อมต่อกับระบบ iRisk เพื่อส่งข้อมูลความเสี่ยงของแต่ละ MOC ไปให้ระบบ iRisk ผ่าน API 4. รองรับการเชื่อมต่อกับระบบ PIS (หรือระบบ HR) เพื่อดึงข้อมูลพนักงาน, โครงสร้างองค์กร, สายบังคับบัญชา เพื่อใช้ในการ 5. รองรับการเชื่อมต่อกับระบบ Ship เพื่อส่งข้อมูลงาน MOC ให้กับระบบ ship ผ่าน API WSO2 6. รองรับการเชื่อมต่อกับระบบ Aims เพื่อส่งข้อมูลงาน MOC ให้กับระบบ Aims ผ่าน API WSO2 | F27: 394900 | G27: Required
A28: =A27+1 -> 13 | B28: Business Requirement | D28: ค่าแรง | E28: 1. สามารถส่งเมลแจ้งผู้เกี่ยวข้องเมื่อได้รับมอบหมายงานในขั้นตอนต่างๆ ได้ 2. สามารถส่งเมลแจ้งผู้เกี่ยวข้องเพื่อแจ้งเตือนสถานะของ MOC 2.1 ระบบส่งเมล Monthly Progress Report เพื่อสรุปรายการ MOC ที่เกี่ยวข้องและอยู่ระหว่างดำเนินการให้กับผู้เกี่ยวข้องอัตโนมัติทุกเดือน 2.2 ระบบส่งเมลแจ้ง Admin, Project engineer, Review team, Manage review team สำหรับรายการ MOC ที่ต้องติดตามเป็นพิเศษ ได้แก่ 2.2.1 Temporary MOC ที่ใกล้หมดอายุ 2.2.2 Temporary MOC ที่หมดอายุแล้ว 2.2.3 MOC ที่ไม่มีการเคลื่อนไหวเป็นเวลานาน 2.3 เตือนงาน ก่อนครบกำหนดแล้วเสร็จ, ครบกำหนดแล้วเสร็จ, ครบกำหนดรื้อถอนงาน Temporary change 2.4 Override - ครบกำหนดติดตามงาน >ติดตาม Task งาน override เกิน 3 วัน 2.5 Override - ครบกำหนดติดตามงาน override ไม่เกิน 3 วัน 2.6 Override - งาน Override ไม่เกิน 3 วัน แจ้งตือนเมื่ออนุมัติครบกำหนด 48 ชั่วโมง, ครบกำหนด 72 ชั่วโมง | F28: 169950 | G28: Required
A29: =A28+1 -> 14 | B29: Business Requirement | D29: ค่าแรง | E29: การออกรายงาน และ Dashbaord 1. สามารถออกรายงาน MOC Status Summary Report ได้ 2. สามารถออกรายงาน MOC Status Progress Summary Report 3. สามารถ Export รายการ MOC ที่อยู่ระหว่างดำเนินการในรูปแบบ Excel ได้ 4. สามารถออกรายงาน MOC Active Status ได้ 5. สามารถออกรายงาน MOC Dashboard ได้ 6. สามารถออกรายงาน MOC: Quality, Process, Law, Safety Health & Environment Report 7. สามารถออกรายงาน MOC: Classification report 8. สามารถออกรายงาน Override: Overall Plant Report 9. สามารถออกรายงาน Dashboard Overall Plant Status 10. ออกรายงาน KPI Report ได้ 11. สามารถ generate file PDF จากข้อมูล MOC ได้ | F29: 326700 | G29: Required
... A39: =A38+1 -> 24 | B39: Business Requirement | D39: ค่าแรง | E39: EPT MOC - Override <= 3 Day | F39: 174900 | G39: Required
A40: =A39+1 -> 25 | B40: Business Requirement | D40: ค่าแรง | E40: EPT Manage Work Flow | F40: =320100 -> 320100 | G40: Required
A41: =A40+1 -> 26 | B41: Business Requirement | D41: ค่าแรง | E41: EPT Report | F41: 446600 | G41: Required
A42: =A41+1 -> 27 | B42: Business Requirement | D42: ค่าแรง | E42: EPT Email Notification | F42: 72050 | G42: Required
A43: =A42+1 -> 28 | B43: Technical Requirement | D43: ค่าแรง | E43: Testing SIT, UAT | F43: 433500 | G43: Required
A44: =A43+1 -> 29 | B44: Technical Requirement | D44: ค่าแรง | E44: Training, Document | F44: 51000 | G44: Required
A45: =A44+1 -> 30 | B45: Deployment | D45: ค่าแรง | E45: Infrastructure | F45: 102000 | G45: Required
A46: =A45+1 -> 31 | B46: Deployment | D46: ค่าแรง | E46: Data migration | F46: =229500+'Vendor Cost'!F7 -> 229500 | G46: Required
A47: =A46+1 -> 32 | B47: Deployment | D47: ค่าแรง | E47: Security Scan | F47: 76500 | G47: Required
A48: =A47+1 -> 33 | B48: Deployment | D48: ค่าแรง | E48: WSO2 API Team | F48: 99000 | G48: Required
A49: =A48+1 -> 34 | B49: Deployment | D49: ค่าแรง | E49: CA&A | F49: 17000 | G49: Required
...

Sheet Cost Brakedown Templete
S3: Group 1 | T3: Group 2 | U3: Group 3 | V3: Total
R4: Bath | S4: =P8 -> 2987500 | T4: =P15 -> 8294500 | U4: =P20 -> 651500 | V4: =SUM(S4:U4) -> 11933500
R5: Rate | S5: =S4/V4 -> 0.25034567 | T5: =T4/V4 -> 0.69506012 | U5: =U4/V4 -> 0.05459421
A8: Group 1 | B8: Project Management & Requirement | P8: =SUM(P9:P10) -> 2987500 | R8: Funtional Requirement
B9: PM | P9: =SUM(ICT_Manday!E62:E63) -> 2520000 | R9: Technical Requirement
B10: BA | P10: =ICT_Manday!F64 -> 467500
A13: Group 2 | B13: PPS | C13: Rate | D13: Technical Lead | E13: SA | F13: UX/UI | G13: Trainer | H13: Dev | I13: Dev (Unit Test) | J13: Tester Vendor | K13: Tester Digital | L13: Dev | M13: Tester | N13: Total withoit Unit Test | O13: Unit Test | P13: Total
L14: =SUM(L15:L16) -> 0 | M14: =SUM(M15:M16) -> 0 | O14: =SUM(O15:O16) -> 0
A15: 2.1 | B15: Business Requirement | P15: =SUM(P16:P18) -> 8294500
A16: 1 | B16: Business Requirement | H16: ='Grand Total'!H12 -> 7810000 | P16: =SUM(D16:H16) -> 7810000
A17: 8 | B17: Testing SIT, UAT | K17: =ICT_Manday!G64 -> 433500 | L17: =SUM(D17:I17) -> 0 | M17: =SUM(J17:K17) -> 433500 | P17: =M17 -> 433500
A18: 9 | B18: Training, Document | P18: =8500*6 -> 51000
A20: Group 3 | B20: Technical Consult Team | P20: =P21+P22+P23+P31+P32+P33 -> 651500
A21: 10 | B21: Infrastructure | P21: =ICT_Manday!M64 -> 102000
A22: 11 | B22: Data migration | P22: =SUM(ICT_Manday!H28:H31)*8500 -> 229500
A23: 11 | B23: Security Scan | P23: =SUM(P24:P30) -> 76500
B24: Source Code Scan (Coverity and Black Duck) | P24: 8500
B25: Container Image Scan (Trivy) | P25: 8500
B26: Security Scan (OWASP ZAP) | P26: 8500
B27: Quality Scan (SonarQube) | P27: 8500
B28: Automatic Test (Robot framework) | P28: 8500
B29: Performance Test (JMeter) | P29: 8500
B30: Web scan (Acunetix) | P30: =SUM(ICT_Manday!N62:N63) -> 25500
A31: 12 | B31: WSO2 | P31: =SUM(ICT_Manday!I64:J64) -> 99000
A32: 13 | B32: CA&A | P32: =ICT_Manday!K64 -> 17000
A33: 14 | B33: Deploy Production | P33: =8500*15 -> 127500
